2025-02-13 19:32:00,195 ERROR scheduler Exception in Enqueue Events for Site commands-site-O4PN2QK.test
Traceback (most recent call last):
  File "/home/johnatas/nexforce/apps/frappe/frappe/utils/scheduler.py", line 105, in enqueue_events_for_site
    if is_scheduler_inactive():
  File "/home/johnatas/nexforce/apps/frappe/frappe/utils/scheduler.py", line 149, in is_scheduler_inactive
    if is_scheduler_disabled(verbose=verbose):
  File "/home/johnatas/nexforce/apps/frappe/frappe/utils/scheduler.py", line 162, in is_scheduler_disabled
    frappe.db.get_single_value("System Settings", "enable_scheduler")
  File "/home/johnatas/nexforce/apps/frappe/frappe/database/database.py", line 869, in get_single_value
    ).run()
  File "/home/johnatas/nexforce/apps/frappe/frappe/query_builder/utils.py", line 84, in execute_query
    result = frappe.db.sql(query, params, *args, **kwargs)  # nosemgrep
  File "/home/johnatas/nexforce/apps/frappe/frappe/database/database.py", line 215, in sql
    self.connect()
  File "/home/johnatas/nexforce/apps/frappe/frappe/database/database.py", line 120, in connect
    self._conn: MariadbConnection | PostgresConnection = self.get_connection()
  File "/home/johnatas/nexforce/apps/frappe/frappe/database/mariadb/database.py", line 107, in get_connection
    conn = self._get_connection()
  File "/home/johnatas/nexforce/apps/frappe/frappe/database/mariadb/database.py", line 113, in _get_connection
    return self.create_connection()
  File "/home/johnatas/nexforce/apps/frappe/frappe/database/mariadb/database.py", line 116, in create_connection
    return pymysql.connect(**self.get_connection_settings())
  File "/home/johnatas/nexforce/env/lib/python3.10/site-packages/pymysql/connections.py", line 361, in __init__
    self.connect()
  File "/home/johnatas/nexforce/env/lib/python3.10/site-packages/pymysql/connections.py", line 669, in connect
    self._request_authentication()
  File "/home/johnatas/nexforce/env/lib/python3.10/site-packages/pymysql/connections.py", line 957, in _request_authentication
    auth_packet = self._read_packet()
  File "/home/johnatas/nexforce/env/lib/python3.10/site-packages/pymysql/connections.py", line 775, in _read_packet
    packet.raise_for_error()
  File "/home/johnatas/nexforce/env/lib/python3.10/site-packages/pymysql/protocol.py", line 219, in raise_for_error
    err.raise_mysql_exception(self._data)
  File "/home/johnatas/nexforce/env/lib/python3.10/site-packages/pymysql/err.py", line 150, in raise_mysql_exception
    raise errorclass(errno, errval)
pymysql.err.OperationalError: (1045, "Access denied for user '_b7ebe10d1e52525e'@'localhost' (using password: YES)")
2025-02-13 19:36:00,556 ERROR scheduler Exception in Enqueue Events for Site commands-site-O4PN2QK.test
Traceback (most recent call last):
  File "/home/johnatas/nexforce/apps/frappe/frappe/utils/scheduler.py", line 105, in enqueue_events_for_site
    if is_scheduler_inactive():
  File "/home/johnatas/nexforce/apps/frappe/frappe/utils/scheduler.py", line 149, in is_scheduler_inactive
    if is_scheduler_disabled(verbose=verbose):
  File "/home/johnatas/nexforce/apps/frappe/frappe/utils/scheduler.py", line 162, in is_scheduler_disabled
    frappe.db.get_single_value("System Settings", "enable_scheduler")
  File "/home/johnatas/nexforce/apps/frappe/frappe/database/database.py", line 869, in get_single_value
    ).run()
  File "/home/johnatas/nexforce/apps/frappe/frappe/query_builder/utils.py", line 84, in execute_query
    result = frappe.db.sql(query, params, *args, **kwargs)  # nosemgrep
  File "/home/johnatas/nexforce/apps/frappe/frappe/database/database.py", line 215, in sql
    self.connect()
  File "/home/johnatas/nexforce/apps/frappe/frappe/database/database.py", line 120, in connect
    self._conn: MariadbConnection | PostgresConnection = self.get_connection()
  File "/home/johnatas/nexforce/apps/frappe/frappe/database/mariadb/database.py", line 107, in get_connection
    conn = self._get_connection()
  File "/home/johnatas/nexforce/apps/frappe/frappe/database/mariadb/database.py", line 113, in _get_connection
    return self.create_connection()
  File "/home/johnatas/nexforce/apps/frappe/frappe/database/mariadb/database.py", line 116, in create_connection
    return pymysql.connect(**self.get_connection_settings())
  File "/home/johnatas/nexforce/env/lib/python3.10/site-packages/pymysql/connections.py", line 361, in __init__
    self.connect()
  File "/home/johnatas/nexforce/env/lib/python3.10/site-packages/pymysql/connections.py", line 669, in connect
    self._request_authentication()
  File "/home/johnatas/nexforce/env/lib/python3.10/site-packages/pymysql/connections.py", line 957, in _request_authentication
    auth_packet = self._read_packet()
  File "/home/johnatas/nexforce/env/lib/python3.10/site-packages/pymysql/connections.py", line 775, in _read_packet
    packet.raise_for_error()
  File "/home/johnatas/nexforce/env/lib/python3.10/site-packages/pymysql/protocol.py", line 219, in raise_for_error
    err.raise_mysql_exception(self._data)
  File "/home/johnatas/nexforce/env/lib/python3.10/site-packages/pymysql/err.py", line 150, in raise_mysql_exception
    raise errorclass(errno, errval)
pymysql.err.OperationalError: (1045, "Access denied for user '_b7ebe10d1e52525e'@'localhost' (using password: YES)")
2025-02-13 19:40:00,975 ERROR scheduler Exception in Enqueue Events for Site commands-site-O4PN2QK.test
Traceback (most recent call last):
  File "/home/johnatas/nexforce/apps/frappe/frappe/utils/scheduler.py", line 105, in enqueue_events_for_site
    if is_scheduler_inactive():
  File "/home/johnatas/nexforce/apps/frappe/frappe/utils/scheduler.py", line 149, in is_scheduler_inactive
    if is_scheduler_disabled(verbose=verbose):
  File "/home/johnatas/nexforce/apps/frappe/frappe/utils/scheduler.py", line 162, in is_scheduler_disabled
    frappe.db.get_single_value("System Settings", "enable_scheduler")
  File "/home/johnatas/nexforce/apps/frappe/frappe/database/database.py", line 869, in get_single_value
    ).run()
  File "/home/johnatas/nexforce/apps/frappe/frappe/query_builder/utils.py", line 84, in execute_query
    result = frappe.db.sql(query, params, *args, **kwargs)  # nosemgrep
  File "/home/johnatas/nexforce/apps/frappe/frappe/database/database.py", line 215, in sql
    self.connect()
  File "/home/johnatas/nexforce/apps/frappe/frappe/database/database.py", line 120, in connect
    self._conn: MariadbConnection | PostgresConnection = self.get_connection()
  File "/home/johnatas/nexforce/apps/frappe/frappe/database/mariadb/database.py", line 107, in get_connection
    conn = self._get_connection()
  File "/home/johnatas/nexforce/apps/frappe/frappe/database/mariadb/database.py", line 113, in _get_connection
    return self.create_connection()
  File "/home/johnatas/nexforce/apps/frappe/frappe/database/mariadb/database.py", line 116, in create_connection
    return pymysql.connect(**self.get_connection_settings())
  File "/home/johnatas/nexforce/env/lib/python3.10/site-packages/pymysql/connections.py", line 361, in __init__
    self.connect()
  File "/home/johnatas/nexforce/env/lib/python3.10/site-packages/pymysql/connections.py", line 669, in connect
    self._request_authentication()
  File "/home/johnatas/nexforce/env/lib/python3.10/site-packages/pymysql/connections.py", line 957, in _request_authentication
    auth_packet = self._read_packet()
  File "/home/johnatas/nexforce/env/lib/python3.10/site-packages/pymysql/connections.py", line 775, in _read_packet
    packet.raise_for_error()
  File "/home/johnatas/nexforce/env/lib/python3.10/site-packages/pymysql/protocol.py", line 219, in raise_for_error
    err.raise_mysql_exception(self._data)
  File "/home/johnatas/nexforce/env/lib/python3.10/site-packages/pymysql/err.py", line 150, in raise_mysql_exception
    raise errorclass(errno, errval)
pymysql.err.OperationalError: (1045, "Access denied for user '_b7ebe10d1e52525e'@'localhost' (using password: YES)")
2025-02-13 19:44:00,294 ERROR scheduler Exception in Enqueue Events for Site commands-site-O4PN2QK.test
Traceback (most recent call last):
  File "/home/johnatas/nexforce/apps/frappe/frappe/utils/scheduler.py", line 105, in enqueue_events_for_site
    if is_scheduler_inactive():
  File "/home/johnatas/nexforce/apps/frappe/frappe/utils/scheduler.py", line 149, in is_scheduler_inactive
    if is_scheduler_disabled(verbose=verbose):
  File "/home/johnatas/nexforce/apps/frappe/frappe/utils/scheduler.py", line 162, in is_scheduler_disabled
    frappe.db.get_single_value("System Settings", "enable_scheduler")
  File "/home/johnatas/nexforce/apps/frappe/frappe/database/database.py", line 869, in get_single_value
    ).run()
  File "/home/johnatas/nexforce/apps/frappe/frappe/query_builder/utils.py", line 84, in execute_query
    result = frappe.db.sql(query, params, *args, **kwargs)  # nosemgrep
  File "/home/johnatas/nexforce/apps/frappe/frappe/database/database.py", line 215, in sql
    self.connect()
  File "/home/johnatas/nexforce/apps/frappe/frappe/database/database.py", line 120, in connect
    self._conn: MariadbConnection | PostgresConnection = self.get_connection()
  File "/home/johnatas/nexforce/apps/frappe/frappe/database/mariadb/database.py", line 107, in get_connection
    conn = self._get_connection()
  File "/home/johnatas/nexforce/apps/frappe/frappe/database/mariadb/database.py", line 113, in _get_connection
    return self.create_connection()
  File "/home/johnatas/nexforce/apps/frappe/frappe/database/mariadb/database.py", line 116, in create_connection
    return pymysql.connect(**self.get_connection_settings())
  File "/home/johnatas/nexforce/env/lib/python3.10/site-packages/pymysql/connections.py", line 361, in __init__
    self.connect()
  File "/home/johnatas/nexforce/env/lib/python3.10/site-packages/pymysql/connections.py", line 669, in connect
    self._request_authentication()
  File "/home/johnatas/nexforce/env/lib/python3.10/site-packages/pymysql/connections.py", line 957, in _request_authentication
    auth_packet = self._read_packet()
  File "/home/johnatas/nexforce/env/lib/python3.10/site-packages/pymysql/connections.py", line 775, in _read_packet
    packet.raise_for_error()
  File "/home/johnatas/nexforce/env/lib/python3.10/site-packages/pymysql/protocol.py", line 219, in raise_for_error
    err.raise_mysql_exception(self._data)
  File "/home/johnatas/nexforce/env/lib/python3.10/site-packages/pymysql/err.py", line 150, in raise_mysql_exception
    raise errorclass(errno, errval)
pymysql.err.OperationalError: (1045, "Access denied for user '_b7ebe10d1e52525e'@'localhost' (using password: YES)")
2025-02-13 19:48:00,946 ERROR scheduler Exception in Enqueue Events for Site commands-site-O4PN2QK.test
Traceback (most recent call last):
  File "/home/johnatas/nexforce/apps/frappe/frappe/utils/scheduler.py", line 105, in enqueue_events_for_site
    if is_scheduler_inactive():
  File "/home/johnatas/nexforce/apps/frappe/frappe/utils/scheduler.py", line 149, in is_scheduler_inactive
    if is_scheduler_disabled(verbose=verbose):
  File "/home/johnatas/nexforce/apps/frappe/frappe/utils/scheduler.py", line 162, in is_scheduler_disabled
    frappe.db.get_single_value("System Settings", "enable_scheduler")
  File "/home/johnatas/nexforce/apps/frappe/frappe/database/database.py", line 869, in get_single_value
    ).run()
  File "/home/johnatas/nexforce/apps/frappe/frappe/query_builder/utils.py", line 84, in execute_query
    result = frappe.db.sql(query, params, *args, **kwargs)  # nosemgrep
  File "/home/johnatas/nexforce/apps/frappe/frappe/database/database.py", line 215, in sql
    self.connect()
  File "/home/johnatas/nexforce/apps/frappe/frappe/database/database.py", line 120, in connect
    self._conn: MariadbConnection | PostgresConnection = self.get_connection()
  File "/home/johnatas/nexforce/apps/frappe/frappe/database/mariadb/database.py", line 107, in get_connection
    conn = self._get_connection()
  File "/home/johnatas/nexforce/apps/frappe/frappe/database/mariadb/database.py", line 113, in _get_connection
    return self.create_connection()
  File "/home/johnatas/nexforce/apps/frappe/frappe/database/mariadb/database.py", line 116, in create_connection
    return pymysql.connect(**self.get_connection_settings())
  File "/home/johnatas/nexforce/env/lib/python3.10/site-packages/pymysql/connections.py", line 361, in __init__
    self.connect()
  File "/home/johnatas/nexforce/env/lib/python3.10/site-packages/pymysql/connections.py", line 669, in connect
    self._request_authentication()
  File "/home/johnatas/nexforce/env/lib/python3.10/site-packages/pymysql/connections.py", line 957, in _request_authentication
    auth_packet = self._read_packet()
  File "/home/johnatas/nexforce/env/lib/python3.10/site-packages/pymysql/connections.py", line 775, in _read_packet
    packet.raise_for_error()
  File "/home/johnatas/nexforce/env/lib/python3.10/site-packages/pymysql/protocol.py", line 219, in raise_for_error
    err.raise_mysql_exception(self._data)
  File "/home/johnatas/nexforce/env/lib/python3.10/site-packages/pymysql/err.py", line 150, in raise_mysql_exception
    raise errorclass(errno, errval)
pymysql.err.OperationalError: (1045, "Access denied for user '_b7ebe10d1e52525e'@'localhost' (using password: YES)")
2025-02-13 19:52:00,273 ERROR scheduler Exception in Enqueue Events for Site commands-site-O4PN2QK.test
Traceback (most recent call last):
  File "/home/johnatas/nexforce/apps/frappe/frappe/utils/scheduler.py", line 105, in enqueue_events_for_site
    if is_scheduler_inactive():
  File "/home/johnatas/nexforce/apps/frappe/frappe/utils/scheduler.py", line 149, in is_scheduler_inactive
    if is_scheduler_disabled(verbose=verbose):
  File "/home/johnatas/nexforce/apps/frappe/frappe/utils/scheduler.py", line 162, in is_scheduler_disabled
    frappe.db.get_single_value("System Settings", "enable_scheduler")
  File "/home/johnatas/nexforce/apps/frappe/frappe/database/database.py", line 869, in get_single_value
    ).run()
  File "/home/johnatas/nexforce/apps/frappe/frappe/query_builder/utils.py", line 84, in execute_query
    result = frappe.db.sql(query, params, *args, **kwargs)  # nosemgrep
  File "/home/johnatas/nexforce/apps/frappe/frappe/database/database.py", line 215, in sql
    self.connect()
  File "/home/johnatas/nexforce/apps/frappe/frappe/database/database.py", line 120, in connect
    self._conn: MariadbConnection | PostgresConnection = self.get_connection()
  File "/home/johnatas/nexforce/apps/frappe/frappe/database/mariadb/database.py", line 107, in get_connection
    conn = self._get_connection()
  File "/home/johnatas/nexforce/apps/frappe/frappe/database/mariadb/database.py", line 113, in _get_connection
    return self.create_connection()
  File "/home/johnatas/nexforce/apps/frappe/frappe/database/mariadb/database.py", line 116, in create_connection
    return pymysql.connect(**self.get_connection_settings())
  File "/home/johnatas/nexforce/env/lib/python3.10/site-packages/pymysql/connections.py", line 361, in __init__
    self.connect()
  File "/home/johnatas/nexforce/env/lib/python3.10/site-packages/pymysql/connections.py", line 669, in connect
    self._request_authentication()
  File "/home/johnatas/nexforce/env/lib/python3.10/site-packages/pymysql/connections.py", line 957, in _request_authentication
    auth_packet = self._read_packet()
  File "/home/johnatas/nexforce/env/lib/python3.10/site-packages/pymysql/connections.py", line 775, in _read_packet
    packet.raise_for_error()
  File "/home/johnatas/nexforce/env/lib/python3.10/site-packages/pymysql/protocol.py", line 219, in raise_for_error
    err.raise_mysql_exception(self._data)
  File "/home/johnatas/nexforce/env/lib/python3.10/site-packages/pymysql/err.py", line 150, in raise_mysql_exception
    raise errorclass(errno, errval)
pymysql.err.OperationalError: (1045, "Access denied for user '_b7ebe10d1e52525e'@'localhost' (using password: YES)")
2025-02-13 19:56:00,502 ERROR scheduler Exception in Enqueue Events for Site commands-site-O4PN2QK.test
Traceback (most recent call last):
  File "/home/johnatas/nexforce/apps/frappe/frappe/utils/scheduler.py", line 105, in enqueue_events_for_site
    if is_scheduler_inactive():
  File "/home/johnatas/nexforce/apps/frappe/frappe/utils/scheduler.py", line 149, in is_scheduler_inactive
    if is_scheduler_disabled(verbose=verbose):
  File "/home/johnatas/nexforce/apps/frappe/frappe/utils/scheduler.py", line 162, in is_scheduler_disabled
    frappe.db.get_single_value("System Settings", "enable_scheduler")
  File "/home/johnatas/nexforce/apps/frappe/frappe/database/database.py", line 869, in get_single_value
    ).run()
  File "/home/johnatas/nexforce/apps/frappe/frappe/query_builder/utils.py", line 84, in execute_query
    result = frappe.db.sql(query, params, *args, **kwargs)  # nosemgrep
  File "/home/johnatas/nexforce/apps/frappe/frappe/database/database.py", line 215, in sql
    self.connect()
  File "/home/johnatas/nexforce/apps/frappe/frappe/database/database.py", line 120, in connect
    self._conn: MariadbConnection | PostgresConnection = self.get_connection()
  File "/home/johnatas/nexforce/apps/frappe/frappe/database/mariadb/database.py", line 107, in get_connection
    conn = self._get_connection()
  File "/home/johnatas/nexforce/apps/frappe/frappe/database/mariadb/database.py", line 113, in _get_connection
    return self.create_connection()
  File "/home/johnatas/nexforce/apps/frappe/frappe/database/mariadb/database.py", line 116, in create_connection
    return pymysql.connect(**self.get_connection_settings())
  File "/home/johnatas/nexforce/env/lib/python3.10/site-packages/pymysql/connections.py", line 361, in __init__
    self.connect()
  File "/home/johnatas/nexforce/env/lib/python3.10/site-packages/pymysql/connections.py", line 669, in connect
    self._request_authentication()
  File "/home/johnatas/nexforce/env/lib/python3.10/site-packages/pymysql/connections.py", line 957, in _request_authentication
    auth_packet = self._read_packet()
  File "/home/johnatas/nexforce/env/lib/python3.10/site-packages/pymysql/connections.py", line 775, in _read_packet
    packet.raise_for_error()
  File "/home/johnatas/nexforce/env/lib/python3.10/site-packages/pymysql/protocol.py", line 219, in raise_for_error
    err.raise_mysql_exception(self._data)
  File "/home/johnatas/nexforce/env/lib/python3.10/site-packages/pymysql/err.py", line 150, in raise_mysql_exception
    raise errorclass(errno, errval)
pymysql.err.OperationalError: (1045, "Access denied for user '_b7ebe10d1e52525e'@'localhost' (using password: YES)")
2025-02-13 20:00:00,803 ERROR scheduler Exception in Enqueue Events for Site commands-site-O4PN2QK.test
Traceback (most recent call last):
  File "/home/johnatas/nexforce/apps/frappe/frappe/utils/scheduler.py", line 105, in enqueue_events_for_site
    if is_scheduler_inactive():
  File "/home/johnatas/nexforce/apps/frappe/frappe/utils/scheduler.py", line 149, in is_scheduler_inactive
    if is_scheduler_disabled(verbose=verbose):
  File "/home/johnatas/nexforce/apps/frappe/frappe/utils/scheduler.py", line 162, in is_scheduler_disabled
    frappe.db.get_single_value("System Settings", "enable_scheduler")
  File "/home/johnatas/nexforce/apps/frappe/frappe/database/database.py", line 869, in get_single_value
    ).run()
  File "/home/johnatas/nexforce/apps/frappe/frappe/query_builder/utils.py", line 84, in execute_query
    result = frappe.db.sql(query, params, *args, **kwargs)  # nosemgrep
  File "/home/johnatas/nexforce/apps/frappe/frappe/database/database.py", line 215, in sql
    self.connect()
  File "/home/johnatas/nexforce/apps/frappe/frappe/database/database.py", line 120, in connect
    self._conn: MariadbConnection | PostgresConnection = self.get_connection()
  File "/home/johnatas/nexforce/apps/frappe/frappe/database/mariadb/database.py", line 107, in get_connection
    conn = self._get_connection()
  File "/home/johnatas/nexforce/apps/frappe/frappe/database/mariadb/database.py", line 113, in _get_connection
    return self.create_connection()
  File "/home/johnatas/nexforce/apps/frappe/frappe/database/mariadb/database.py", line 116, in create_connection
    return pymysql.connect(**self.get_connection_settings())
  File "/home/johnatas/nexforce/env/lib/python3.10/site-packages/pymysql/connections.py", line 361, in __init__
    self.connect()
  File "/home/johnatas/nexforce/env/lib/python3.10/site-packages/pymysql/connections.py", line 669, in connect
    self._request_authentication()
  File "/home/johnatas/nexforce/env/lib/python3.10/site-packages/pymysql/connections.py", line 957, in _request_authentication
    auth_packet = self._read_packet()
  File "/home/johnatas/nexforce/env/lib/python3.10/site-packages/pymysql/connections.py", line 775, in _read_packet
    packet.raise_for_error()
  File "/home/johnatas/nexforce/env/lib/python3.10/site-packages/pymysql/protocol.py", line 219, in raise_for_error
    err.raise_mysql_exception(self._data)
  File "/home/johnatas/nexforce/env/lib/python3.10/site-packages/pymysql/err.py", line 150, in raise_mysql_exception
    raise errorclass(errno, errval)
pymysql.err.OperationalError: (1045, "Access denied for user '_b7ebe10d1e52525e'@'localhost' (using password: YES)")
2025-02-13 20:08:00,909 ERROR scheduler Exception in Enqueue Events for Site commands-site-O4PN2QK.test
Traceback (most recent call last):
  File "/home/johnatas/nexforce/apps/frappe/frappe/utils/scheduler.py", line 105, in enqueue_events_for_site
    if is_scheduler_inactive():
  File "/home/johnatas/nexforce/apps/frappe/frappe/utils/scheduler.py", line 149, in is_scheduler_inactive
    if is_scheduler_disabled(verbose=verbose):
  File "/home/johnatas/nexforce/apps/frappe/frappe/utils/scheduler.py", line 162, in is_scheduler_disabled
    frappe.db.get_single_value("System Settings", "enable_scheduler")
  File "/home/johnatas/nexforce/apps/frappe/frappe/database/database.py", line 869, in get_single_value
    ).run()
  File "/home/johnatas/nexforce/apps/frappe/frappe/query_builder/utils.py", line 84, in execute_query
    result = frappe.db.sql(query, params, *args, **kwargs)  # nosemgrep
  File "/home/johnatas/nexforce/apps/frappe/frappe/database/database.py", line 215, in sql
    self.connect()
  File "/home/johnatas/nexforce/apps/frappe/frappe/database/database.py", line 120, in connect
    self._conn: MariadbConnection | PostgresConnection = self.get_connection()
  File "/home/johnatas/nexforce/apps/frappe/frappe/database/mariadb/database.py", line 107, in get_connection
    conn = self._get_connection()
  File "/home/johnatas/nexforce/apps/frappe/frappe/database/mariadb/database.py", line 113, in _get_connection
    return self.create_connection()
  File "/home/johnatas/nexforce/apps/frappe/frappe/database/mariadb/database.py", line 116, in create_connection
    return pymysql.connect(**self.get_connection_settings())
  File "/home/johnatas/nexforce/env/lib/python3.10/site-packages/pymysql/connections.py", line 361, in __init__
    self.connect()
  File "/home/johnatas/nexforce/env/lib/python3.10/site-packages/pymysql/connections.py", line 669, in connect
    self._request_authentication()
  File "/home/johnatas/nexforce/env/lib/python3.10/site-packages/pymysql/connections.py", line 957, in _request_authentication
    auth_packet = self._read_packet()
  File "/home/johnatas/nexforce/env/lib/python3.10/site-packages/pymysql/connections.py", line 775, in _read_packet
    packet.raise_for_error()
  File "/home/johnatas/nexforce/env/lib/python3.10/site-packages/pymysql/protocol.py", line 219, in raise_for_error
    err.raise_mysql_exception(self._data)
  File "/home/johnatas/nexforce/env/lib/python3.10/site-packages/pymysql/err.py", line 150, in raise_mysql_exception
    raise errorclass(errno, errval)
pymysql.err.OperationalError: (1045, "Access denied for user '_b7ebe10d1e52525e'@'localhost' (using password: YES)")
2025-02-13 20:12:00,691 ERROR scheduler Exception in Enqueue Events for Site commands-site-O4PN2QK.test
Traceback (most recent call last):
  File "/home/johnatas/nexforce/apps/frappe/frappe/utils/scheduler.py", line 105, in enqueue_events_for_site
    if is_scheduler_inactive():
  File "/home/johnatas/nexforce/apps/frappe/frappe/utils/scheduler.py", line 149, in is_scheduler_inactive
    if is_scheduler_disabled(verbose=verbose):
  File "/home/johnatas/nexforce/apps/frappe/frappe/utils/scheduler.py", line 162, in is_scheduler_disabled
    frappe.db.get_single_value("System Settings", "enable_scheduler")
  File "/home/johnatas/nexforce/apps/frappe/frappe/database/database.py", line 869, in get_single_value
    ).run()
  File "/home/johnatas/nexforce/apps/frappe/frappe/query_builder/utils.py", line 84, in execute_query
    result = frappe.db.sql(query, params, *args, **kwargs)  # nosemgrep
  File "/home/johnatas/nexforce/apps/frappe/frappe/database/database.py", line 215, in sql
    self.connect()
  File "/home/johnatas/nexforce/apps/frappe/frappe/database/database.py", line 120, in connect
    self._conn: MariadbConnection | PostgresConnection = self.get_connection()
  File "/home/johnatas/nexforce/apps/frappe/frappe/database/mariadb/database.py", line 107, in get_connection
    conn = self._get_connection()
  File "/home/johnatas/nexforce/apps/frappe/frappe/database/mariadb/database.py", line 113, in _get_connection
    return self.create_connection()
  File "/home/johnatas/nexforce/apps/frappe/frappe/database/mariadb/database.py", line 116, in create_connection
    return pymysql.connect(**self.get_connection_settings())
  File "/home/johnatas/nexforce/env/lib/python3.10/site-packages/pymysql/connections.py", line 361, in __init__
    self.connect()
  File "/home/johnatas/nexforce/env/lib/python3.10/site-packages/pymysql/connections.py", line 669, in connect
    self._request_authentication()
  File "/home/johnatas/nexforce/env/lib/python3.10/site-packages/pymysql/connections.py", line 957, in _request_authentication
    auth_packet = self._read_packet()
  File "/home/johnatas/nexforce/env/lib/python3.10/site-packages/pymysql/connections.py", line 775, in _read_packet
    packet.raise_for_error()
  File "/home/johnatas/nexforce/env/lib/python3.10/site-packages/pymysql/protocol.py", line 219, in raise_for_error
    err.raise_mysql_exception(self._data)
  File "/home/johnatas/nexforce/env/lib/python3.10/site-packages/pymysql/err.py", line 150, in raise_mysql_exception
    raise errorclass(errno, errval)
pymysql.err.OperationalError: (1045, "Access denied for user '_b7ebe10d1e52525e'@'localhost' (using password: YES)")
2025-02-13 20:16:01,036 ERROR scheduler Exception in Enqueue Events for Site commands-site-O4PN2QK.test
Traceback (most recent call last):
  File "/home/johnatas/nexforce/apps/frappe/frappe/utils/scheduler.py", line 105, in enqueue_events_for_site
    if is_scheduler_inactive():
  File "/home/johnatas/nexforce/apps/frappe/frappe/utils/scheduler.py", line 149, in is_scheduler_inactive
    if is_scheduler_disabled(verbose=verbose):
  File "/home/johnatas/nexforce/apps/frappe/frappe/utils/scheduler.py", line 162, in is_scheduler_disabled
    frappe.db.get_single_value("System Settings", "enable_scheduler")
  File "/home/johnatas/nexforce/apps/frappe/frappe/database/database.py", line 869, in get_single_value
    ).run()
  File "/home/johnatas/nexforce/apps/frappe/frappe/query_builder/utils.py", line 84, in execute_query
    result = frappe.db.sql(query, params, *args, **kwargs)  # nosemgrep
  File "/home/johnatas/nexforce/apps/frappe/frappe/database/database.py", line 215, in sql
    self.connect()
  File "/home/johnatas/nexforce/apps/frappe/frappe/database/database.py", line 120, in connect
    self._conn: MariadbConnection | PostgresConnection = self.get_connection()
  File "/home/johnatas/nexforce/apps/frappe/frappe/database/mariadb/database.py", line 107, in get_connection
    conn = self._get_connection()
  File "/home/johnatas/nexforce/apps/frappe/frappe/database/mariadb/database.py", line 113, in _get_connection
    return self.create_connection()
  File "/home/johnatas/nexforce/apps/frappe/frappe/database/mariadb/database.py", line 116, in create_connection
    return pymysql.connect(**self.get_connection_settings())
  File "/home/johnatas/nexforce/env/lib/python3.10/site-packages/pymysql/connections.py", line 361, in __init__
    self.connect()
  File "/home/johnatas/nexforce/env/lib/python3.10/site-packages/pymysql/connections.py", line 669, in connect
    self._request_authentication()
  File "/home/johnatas/nexforce/env/lib/python3.10/site-packages/pymysql/connections.py", line 957, in _request_authentication
    auth_packet = self._read_packet()
  File "/home/johnatas/nexforce/env/lib/python3.10/site-packages/pymysql/connections.py", line 775, in _read_packet
    packet.raise_for_error()
  File "/home/johnatas/nexforce/env/lib/python3.10/site-packages/pymysql/protocol.py", line 219, in raise_for_error
    err.raise_mysql_exception(self._data)
  File "/home/johnatas/nexforce/env/lib/python3.10/site-packages/pymysql/err.py", line 150, in raise_mysql_exception
    raise errorclass(errno, errval)
pymysql.err.OperationalError: (1045, "Access denied for user '_b7ebe10d1e52525e'@'localhost' (using password: YES)")
2025-02-13 20:20:00,144 ERROR scheduler Exception in Enqueue Events for Site commands-site-O4PN2QK.test
Traceback (most recent call last):
  File "/home/johnatas/nexforce/apps/frappe/frappe/utils/scheduler.py", line 105, in enqueue_events_for_site
    if is_scheduler_inactive():
  File "/home/johnatas/nexforce/apps/frappe/frappe/utils/scheduler.py", line 149, in is_scheduler_inactive
    if is_scheduler_disabled(verbose=verbose):
  File "/home/johnatas/nexforce/apps/frappe/frappe/utils/scheduler.py", line 162, in is_scheduler_disabled
    frappe.db.get_single_value("System Settings", "enable_scheduler")
  File "/home/johnatas/nexforce/apps/frappe/frappe/database/database.py", line 869, in get_single_value
    ).run()
  File "/home/johnatas/nexforce/apps/frappe/frappe/query_builder/utils.py", line 84, in execute_query
    result = frappe.db.sql(query, params, *args, **kwargs)  # nosemgrep
  File "/home/johnatas/nexforce/apps/frappe/frappe/database/database.py", line 215, in sql
    self.connect()
  File "/home/johnatas/nexforce/apps/frappe/frappe/database/database.py", line 120, in connect
    self._conn: MariadbConnection | PostgresConnection = self.get_connection()
  File "/home/johnatas/nexforce/apps/frappe/frappe/database/mariadb/database.py", line 107, in get_connection
    conn = self._get_connection()
  File "/home/johnatas/nexforce/apps/frappe/frappe/database/mariadb/database.py", line 113, in _get_connection
    return self.create_connection()
  File "/home/johnatas/nexforce/apps/frappe/frappe/database/mariadb/database.py", line 116, in create_connection
    return pymysql.connect(**self.get_connection_settings())
  File "/home/johnatas/nexforce/env/lib/python3.10/site-packages/pymysql/connections.py", line 361, in __init__
    self.connect()
  File "/home/johnatas/nexforce/env/lib/python3.10/site-packages/pymysql/connections.py", line 669, in connect
    self._request_authentication()
  File "/home/johnatas/nexforce/env/lib/python3.10/site-packages/pymysql/connections.py", line 957, in _request_authentication
    auth_packet = self._read_packet()
  File "/home/johnatas/nexforce/env/lib/python3.10/site-packages/pymysql/connections.py", line 775, in _read_packet
    packet.raise_for_error()
  File "/home/johnatas/nexforce/env/lib/python3.10/site-packages/pymysql/protocol.py", line 219, in raise_for_error
    err.raise_mysql_exception(self._data)
  File "/home/johnatas/nexforce/env/lib/python3.10/site-packages/pymysql/err.py", line 150, in raise_mysql_exception
    raise errorclass(errno, errval)
pymysql.err.OperationalError: (1045, "Access denied for user '_b7ebe10d1e52525e'@'localhost' (using password: YES)")
2025-02-13 20:24:00,490 ERROR scheduler Exception in Enqueue Events for Site commands-site-O4PN2QK.test
Traceback (most recent call last):
  File "/home/johnatas/nexforce/apps/frappe/frappe/utils/scheduler.py", line 105, in enqueue_events_for_site
    if is_scheduler_inactive():
  File "/home/johnatas/nexforce/apps/frappe/frappe/utils/scheduler.py", line 149, in is_scheduler_inactive
    if is_scheduler_disabled(verbose=verbose):
  File "/home/johnatas/nexforce/apps/frappe/frappe/utils/scheduler.py", line 162, in is_scheduler_disabled
    frappe.db.get_single_value("System Settings", "enable_scheduler")
  File "/home/johnatas/nexforce/apps/frappe/frappe/database/database.py", line 869, in get_single_value
    ).run()
  File "/home/johnatas/nexforce/apps/frappe/frappe/query_builder/utils.py", line 84, in execute_query
    result = frappe.db.sql(query, params, *args, **kwargs)  # nosemgrep
  File "/home/johnatas/nexforce/apps/frappe/frappe/database/database.py", line 215, in sql
    self.connect()
  File "/home/johnatas/nexforce/apps/frappe/frappe/database/database.py", line 120, in connect
    self._conn: MariadbConnection | PostgresConnection = self.get_connection()
  File "/home/johnatas/nexforce/apps/frappe/frappe/database/mariadb/database.py", line 107, in get_connection
    conn = self._get_connection()
  File "/home/johnatas/nexforce/apps/frappe/frappe/database/mariadb/database.py", line 113, in _get_connection
    return self.create_connection()
  File "/home/johnatas/nexforce/apps/frappe/frappe/database/mariadb/database.py", line 116, in create_connection
    return pymysql.connect(**self.get_connection_settings())
  File "/home/johnatas/nexforce/env/lib/python3.10/site-packages/pymysql/connections.py", line 361, in __init__
    self.connect()
  File "/home/johnatas/nexforce/env/lib/python3.10/site-packages/pymysql/connections.py", line 669, in connect
    self._request_authentication()
  File "/home/johnatas/nexforce/env/lib/python3.10/site-packages/pymysql/connections.py", line 957, in _request_authentication
    auth_packet = self._read_packet()
  File "/home/johnatas/nexforce/env/lib/python3.10/site-packages/pymysql/connections.py", line 775, in _read_packet
    packet.raise_for_error()
  File "/home/johnatas/nexforce/env/lib/python3.10/site-packages/pymysql/protocol.py", line 219, in raise_for_error
    err.raise_mysql_exception(self._data)
  File "/home/johnatas/nexforce/env/lib/python3.10/site-packages/pymysql/err.py", line 150, in raise_mysql_exception
    raise errorclass(errno, errval)
pymysql.err.OperationalError: (1045, "Access denied for user '_b7ebe10d1e52525e'@'localhost' (using password: YES)")
2025-02-13 20:28:01,123 ERROR scheduler Exception in Enqueue Events for Site commands-site-O4PN2QK.test
Traceback (most recent call last):
  File "/home/johnatas/nexforce/apps/frappe/frappe/utils/scheduler.py", line 105, in enqueue_events_for_site
    if is_scheduler_inactive():
  File "/home/johnatas/nexforce/apps/frappe/frappe/utils/scheduler.py", line 149, in is_scheduler_inactive
    if is_scheduler_disabled(verbose=verbose):
  File "/home/johnatas/nexforce/apps/frappe/frappe/utils/scheduler.py", line 162, in is_scheduler_disabled
    frappe.db.get_single_value("System Settings", "enable_scheduler")
  File "/home/johnatas/nexforce/apps/frappe/frappe/database/database.py", line 869, in get_single_value
    ).run()
  File "/home/johnatas/nexforce/apps/frappe/frappe/query_builder/utils.py", line 84, in execute_query
    result = frappe.db.sql(query, params, *args, **kwargs)  # nosemgrep
  File "/home/johnatas/nexforce/apps/frappe/frappe/database/database.py", line 215, in sql
    self.connect()
  File "/home/johnatas/nexforce/apps/frappe/frappe/database/database.py", line 120, in connect
    self._conn: MariadbConnection | PostgresConnection = self.get_connection()
  File "/home/johnatas/nexforce/apps/frappe/frappe/database/mariadb/database.py", line 107, in get_connection
    conn = self._get_connection()
  File "/home/johnatas/nexforce/apps/frappe/frappe/database/mariadb/database.py", line 113, in _get_connection
    return self.create_connection()
  File "/home/johnatas/nexforce/apps/frappe/frappe/database/mariadb/database.py", line 116, in create_connection
    return pymysql.connect(**self.get_connection_settings())
  File "/home/johnatas/nexforce/env/lib/python3.10/site-packages/pymysql/connections.py", line 361, in __init__
    self.connect()
  File "/home/johnatas/nexforce/env/lib/python3.10/site-packages/pymysql/connections.py", line 669, in connect
    self._request_authentication()
  File "/home/johnatas/nexforce/env/lib/python3.10/site-packages/pymysql/connections.py", line 957, in _request_authentication
    auth_packet = self._read_packet()
  File "/home/johnatas/nexforce/env/lib/python3.10/site-packages/pymysql/connections.py", line 775, in _read_packet
    packet.raise_for_error()
  File "/home/johnatas/nexforce/env/lib/python3.10/site-packages/pymysql/protocol.py", line 219, in raise_for_error
    err.raise_mysql_exception(self._data)
  File "/home/johnatas/nexforce/env/lib/python3.10/site-packages/pymysql/err.py", line 150, in raise_mysql_exception
    raise errorclass(errno, errval)
pymysql.err.OperationalError: (1045, "Access denied for user '_b7ebe10d1e52525e'@'localhost' (using password: YES)")
2025-02-13 20:32:00,137 ERROR scheduler Exception in Enqueue Events for Site commands-site-O4PN2QK.test
Traceback (most recent call last):
  File "/home/johnatas/nexforce/apps/frappe/frappe/utils/scheduler.py", line 105, in enqueue_events_for_site
    if is_scheduler_inactive():
  File "/home/johnatas/nexforce/apps/frappe/frappe/utils/scheduler.py", line 149, in is_scheduler_inactive
    if is_scheduler_disabled(verbose=verbose):
  File "/home/johnatas/nexforce/apps/frappe/frappe/utils/scheduler.py", line 162, in is_scheduler_disabled
    frappe.db.get_single_value("System Settings", "enable_scheduler")
  File "/home/johnatas/nexforce/apps/frappe/frappe/database/database.py", line 869, in get_single_value
    ).run()
  File "/home/johnatas/nexforce/apps/frappe/frappe/query_builder/utils.py", line 84, in execute_query
    result = frappe.db.sql(query, params, *args, **kwargs)  # nosemgrep
  File "/home/johnatas/nexforce/apps/frappe/frappe/database/database.py", line 215, in sql
    self.connect()
  File "/home/johnatas/nexforce/apps/frappe/frappe/database/database.py", line 120, in connect
    self._conn: MariadbConnection | PostgresConnection = self.get_connection()
  File "/home/johnatas/nexforce/apps/frappe/frappe/database/mariadb/database.py", line 107, in get_connection
    conn = self._get_connection()
  File "/home/johnatas/nexforce/apps/frappe/frappe/database/mariadb/database.py", line 113, in _get_connection
    return self.create_connection()
  File "/home/johnatas/nexforce/apps/frappe/frappe/database/mariadb/database.py", line 116, in create_connection
    return pymysql.connect(**self.get_connection_settings())
  File "/home/johnatas/nexforce/env/lib/python3.10/site-packages/pymysql/connections.py", line 361, in __init__
    self.connect()
  File "/home/johnatas/nexforce/env/lib/python3.10/site-packages/pymysql/connections.py", line 669, in connect
    self._request_authentication()
  File "/home/johnatas/nexforce/env/lib/python3.10/site-packages/pymysql/connections.py", line 957, in _request_authentication
    auth_packet = self._read_packet()
  File "/home/johnatas/nexforce/env/lib/python3.10/site-packages/pymysql/connections.py", line 775, in _read_packet
    packet.raise_for_error()
  File "/home/johnatas/nexforce/env/lib/python3.10/site-packages/pymysql/protocol.py", line 219, in raise_for_error
    err.raise_mysql_exception(self._data)
  File "/home/johnatas/nexforce/env/lib/python3.10/site-packages/pymysql/err.py", line 150, in raise_mysql_exception
    raise errorclass(errno, errval)
pymysql.err.OperationalError: (1045, "Access denied for user '_b7ebe10d1e52525e'@'localhost' (using password: YES)")
2025-02-16 20:56:01,228 ERROR scheduler Exception in Enqueue Events for Site commands-site-O4PN2QK.test
Traceback (most recent call last):
  File "/home/johnatas/nexforce/apps/frappe/frappe/utils/scheduler.py", line 105, in enqueue_events_for_site
    if is_scheduler_inactive():
  File "/home/johnatas/nexforce/apps/frappe/frappe/utils/scheduler.py", line 149, in is_scheduler_inactive
    if is_scheduler_disabled(verbose=verbose):
  File "/home/johnatas/nexforce/apps/frappe/frappe/utils/scheduler.py", line 162, in is_scheduler_disabled
    frappe.db.get_single_value("System Settings", "enable_scheduler")
  File "/home/johnatas/nexforce/apps/frappe/frappe/database/database.py", line 869, in get_single_value
    ).run()
  File "/home/johnatas/nexforce/apps/frappe/frappe/query_builder/utils.py", line 84, in execute_query
    result = frappe.db.sql(query, params, *args, **kwargs)  # nosemgrep
  File "/home/johnatas/nexforce/apps/frappe/frappe/database/database.py", line 215, in sql
    self.connect()
  File "/home/johnatas/nexforce/apps/frappe/frappe/database/database.py", line 120, in connect
    self._conn: MariadbConnection | PostgresConnection = self.get_connection()
  File "/home/johnatas/nexforce/apps/frappe/frappe/database/mariadb/database.py", line 107, in get_connection
    conn = self._get_connection()
  File "/home/johnatas/nexforce/apps/frappe/frappe/database/mariadb/database.py", line 113, in _get_connection
    return self.create_connection()
  File "/home/johnatas/nexforce/apps/frappe/frappe/database/mariadb/database.py", line 116, in create_connection
    return pymysql.connect(**self.get_connection_settings())
  File "/home/johnatas/nexforce/env/lib/python3.10/site-packages/pymysql/connections.py", line 361, in __init__
    self.connect()
  File "/home/johnatas/nexforce/env/lib/python3.10/site-packages/pymysql/connections.py", line 669, in connect
    self._request_authentication()
  File "/home/johnatas/nexforce/env/lib/python3.10/site-packages/pymysql/connections.py", line 957, in _request_authentication
    auth_packet = self._read_packet()
  File "/home/johnatas/nexforce/env/lib/python3.10/site-packages/pymysql/connections.py", line 775, in _read_packet
    packet.raise_for_error()
  File "/home/johnatas/nexforce/env/lib/python3.10/site-packages/pymysql/protocol.py", line 219, in raise_for_error
    err.raise_mysql_exception(self._data)
  File "/home/johnatas/nexforce/env/lib/python3.10/site-packages/pymysql/err.py", line 150, in raise_mysql_exception
    raise errorclass(errno, errval)
pymysql.err.OperationalError: (1045, "Access denied for user '_b7ebe10d1e52525e'@'localhost' (using password: YES)")
2025-02-16 21:00:00,623 ERROR scheduler Exception in Enqueue Events for Site commands-site-O4PN2QK.test
Traceback (most recent call last):
  File "/home/johnatas/nexforce/apps/frappe/frappe/utils/scheduler.py", line 105, in enqueue_events_for_site
    if is_scheduler_inactive():
  File "/home/johnatas/nexforce/apps/frappe/frappe/utils/scheduler.py", line 149, in is_scheduler_inactive
    if is_scheduler_disabled(verbose=verbose):
  File "/home/johnatas/nexforce/apps/frappe/frappe/utils/scheduler.py", line 162, in is_scheduler_disabled
    frappe.db.get_single_value("System Settings", "enable_scheduler")
  File "/home/johnatas/nexforce/apps/frappe/frappe/database/database.py", line 869, in get_single_value
    ).run()
  File "/home/johnatas/nexforce/apps/frappe/frappe/query_builder/utils.py", line 84, in execute_query
    result = frappe.db.sql(query, params, *args, **kwargs)  # nosemgrep
  File "/home/johnatas/nexforce/apps/frappe/frappe/database/database.py", line 215, in sql
    self.connect()
  File "/home/johnatas/nexforce/apps/frappe/frappe/database/database.py", line 120, in connect
    self._conn: MariadbConnection | PostgresConnection = self.get_connection()
  File "/home/johnatas/nexforce/apps/frappe/frappe/database/mariadb/database.py", line 107, in get_connection
    conn = self._get_connection()
  File "/home/johnatas/nexforce/apps/frappe/frappe/database/mariadb/database.py", line 113, in _get_connection
    return self.create_connection()
  File "/home/johnatas/nexforce/apps/frappe/frappe/database/mariadb/database.py", line 116, in create_connection
    return pymysql.connect(**self.get_connection_settings())
  File "/home/johnatas/nexforce/env/lib/python3.10/site-packages/pymysql/connections.py", line 361, in __init__
    self.connect()
  File "/home/johnatas/nexforce/env/lib/python3.10/site-packages/pymysql/connections.py", line 669, in connect
    self._request_authentication()
  File "/home/johnatas/nexforce/env/lib/python3.10/site-packages/pymysql/connections.py", line 957, in _request_authentication
    auth_packet = self._read_packet()
  File "/home/johnatas/nexforce/env/lib/python3.10/site-packages/pymysql/connections.py", line 775, in _read_packet
    packet.raise_for_error()
  File "/home/johnatas/nexforce/env/lib/python3.10/site-packages/pymysql/protocol.py", line 219, in raise_for_error
    err.raise_mysql_exception(self._data)
  File "/home/johnatas/nexforce/env/lib/python3.10/site-packages/pymysql/err.py", line 150, in raise_mysql_exception
    raise errorclass(errno, errval)
pymysql.err.OperationalError: (1045, "Access denied for user '_b7ebe10d1e52525e'@'localhost' (using password: YES)")
2025-02-16 21:04:00,731 ERROR scheduler Exception in Enqueue Events for Site commands-site-O4PN2QK.test
Traceback (most recent call last):
  File "/home/johnatas/nexforce/apps/frappe/frappe/utils/scheduler.py", line 105, in enqueue_events_for_site
    if is_scheduler_inactive():
  File "/home/johnatas/nexforce/apps/frappe/frappe/utils/scheduler.py", line 149, in is_scheduler_inactive
    if is_scheduler_disabled(verbose=verbose):
  File "/home/johnatas/nexforce/apps/frappe/frappe/utils/scheduler.py", line 162, in is_scheduler_disabled
    frappe.db.get_single_value("System Settings", "enable_scheduler")
  File "/home/johnatas/nexforce/apps/frappe/frappe/database/database.py", line 869, in get_single_value
    ).run()
  File "/home/johnatas/nexforce/apps/frappe/frappe/query_builder/utils.py", line 84, in execute_query
    result = frappe.db.sql(query, params, *args, **kwargs)  # nosemgrep
  File "/home/johnatas/nexforce/apps/frappe/frappe/database/database.py", line 215, in sql
    self.connect()
  File "/home/johnatas/nexforce/apps/frappe/frappe/database/database.py", line 120, in connect
    self._conn: MariadbConnection | PostgresConnection = self.get_connection()
  File "/home/johnatas/nexforce/apps/frappe/frappe/database/mariadb/database.py", line 107, in get_connection
    conn = self._get_connection()
  File "/home/johnatas/nexforce/apps/frappe/frappe/database/mariadb/database.py", line 113, in _get_connection
    return self.create_connection()
  File "/home/johnatas/nexforce/apps/frappe/frappe/database/mariadb/database.py", line 116, in create_connection
    return pymysql.connect(**self.get_connection_settings())
  File "/home/johnatas/nexforce/env/lib/python3.10/site-packages/pymysql/connections.py", line 361, in __init__
    self.connect()
  File "/home/johnatas/nexforce/env/lib/python3.10/site-packages/pymysql/connections.py", line 669, in connect
    self._request_authentication()
  File "/home/johnatas/nexforce/env/lib/python3.10/site-packages/pymysql/connections.py", line 957, in _request_authentication
    auth_packet = self._read_packet()
  File "/home/johnatas/nexforce/env/lib/python3.10/site-packages/pymysql/connections.py", line 775, in _read_packet
    packet.raise_for_error()
  File "/home/johnatas/nexforce/env/lib/python3.10/site-packages/pymysql/protocol.py", line 219, in raise_for_error
    err.raise_mysql_exception(self._data)
  File "/home/johnatas/nexforce/env/lib/python3.10/site-packages/pymysql/err.py", line 150, in raise_mysql_exception
    raise errorclass(errno, errval)
pymysql.err.OperationalError: (1045, "Access denied for user '_b7ebe10d1e52525e'@'localhost' (using password: YES)")
2025-02-16 21:08:01,280 ERROR scheduler Exception in Enqueue Events for Site commands-site-O4PN2QK.test
Traceback (most recent call last):
  File "/home/johnatas/nexforce/apps/frappe/frappe/utils/scheduler.py", line 105, in enqueue_events_for_site
    if is_scheduler_inactive():
  File "/home/johnatas/nexforce/apps/frappe/frappe/utils/scheduler.py", line 149, in is_scheduler_inactive
    if is_scheduler_disabled(verbose=verbose):
  File "/home/johnatas/nexforce/apps/frappe/frappe/utils/scheduler.py", line 162, in is_scheduler_disabled
    frappe.db.get_single_value("System Settings", "enable_scheduler")
  File "/home/johnatas/nexforce/apps/frappe/frappe/database/database.py", line 869, in get_single_value
    ).run()
  File "/home/johnatas/nexforce/apps/frappe/frappe/query_builder/utils.py", line 84, in execute_query
    result = frappe.db.sql(query, params, *args, **kwargs)  # nosemgrep
  File "/home/johnatas/nexforce/apps/frappe/frappe/database/database.py", line 215, in sql
    self.connect()
  File "/home/johnatas/nexforce/apps/frappe/frappe/database/database.py", line 120, in connect
    self._conn: MariadbConnection | PostgresConnection = self.get_connection()
  File "/home/johnatas/nexforce/apps/frappe/frappe/database/mariadb/database.py", line 107, in get_connection
    conn = self._get_connection()
  File "/home/johnatas/nexforce/apps/frappe/frappe/database/mariadb/database.py", line 113, in _get_connection
    return self.create_connection()
  File "/home/johnatas/nexforce/apps/frappe/frappe/database/mariadb/database.py", line 116, in create_connection
    return pymysql.connect(**self.get_connection_settings())
  File "/home/johnatas/nexforce/env/lib/python3.10/site-packages/pymysql/connections.py", line 361, in __init__
    self.connect()
  File "/home/johnatas/nexforce/env/lib/python3.10/site-packages/pymysql/connections.py", line 669, in connect
    self._request_authentication()
  File "/home/johnatas/nexforce/env/lib/python3.10/site-packages/pymysql/connections.py", line 957, in _request_authentication
    auth_packet = self._read_packet()
  File "/home/johnatas/nexforce/env/lib/python3.10/site-packages/pymysql/connections.py", line 775, in _read_packet
    packet.raise_for_error()
  File "/home/johnatas/nexforce/env/lib/python3.10/site-packages/pymysql/protocol.py", line 219, in raise_for_error
    err.raise_mysql_exception(self._data)
  File "/home/johnatas/nexforce/env/lib/python3.10/site-packages/pymysql/err.py", line 150, in raise_mysql_exception
    raise errorclass(errno, errval)
pymysql.err.OperationalError: (1045, "Access denied for user '_b7ebe10d1e52525e'@'localhost' (using password: YES)")
2025-02-16 21:12:00,598 ERROR scheduler Exception in Enqueue Events for Site commands-site-O4PN2QK.test
Traceback (most recent call last):
  File "/home/johnatas/nexforce/apps/frappe/frappe/utils/scheduler.py", line 105, in enqueue_events_for_site
    if is_scheduler_inactive():
  File "/home/johnatas/nexforce/apps/frappe/frappe/utils/scheduler.py", line 149, in is_scheduler_inactive
    if is_scheduler_disabled(verbose=verbose):
  File "/home/johnatas/nexforce/apps/frappe/frappe/utils/scheduler.py", line 162, in is_scheduler_disabled
    frappe.db.get_single_value("System Settings", "enable_scheduler")
  File "/home/johnatas/nexforce/apps/frappe/frappe/database/database.py", line 869, in get_single_value
    ).run()
  File "/home/johnatas/nexforce/apps/frappe/frappe/query_builder/utils.py", line 84, in execute_query
    result = frappe.db.sql(query, params, *args, **kwargs)  # nosemgrep
  File "/home/johnatas/nexforce/apps/frappe/frappe/database/database.py", line 215, in sql
    self.connect()
  File "/home/johnatas/nexforce/apps/frappe/frappe/database/database.py", line 120, in connect
    self._conn: MariadbConnection | PostgresConnection = self.get_connection()
  File "/home/johnatas/nexforce/apps/frappe/frappe/database/mariadb/database.py", line 107, in get_connection
    conn = self._get_connection()
  File "/home/johnatas/nexforce/apps/frappe/frappe/database/mariadb/database.py", line 113, in _get_connection
    return self.create_connection()
  File "/home/johnatas/nexforce/apps/frappe/frappe/database/mariadb/database.py", line 116, in create_connection
    return pymysql.connect(**self.get_connection_settings())
  File "/home/johnatas/nexforce/env/lib/python3.10/site-packages/pymysql/connections.py", line 361, in __init__
    self.connect()
  File "/home/johnatas/nexforce/env/lib/python3.10/site-packages/pymysql/connections.py", line 669, in connect
    self._request_authentication()
  File "/home/johnatas/nexforce/env/lib/python3.10/site-packages/pymysql/connections.py", line 957, in _request_authentication
    auth_packet = self._read_packet()
  File "/home/johnatas/nexforce/env/lib/python3.10/site-packages/pymysql/connections.py", line 775, in _read_packet
    packet.raise_for_error()
  File "/home/johnatas/nexforce/env/lib/python3.10/site-packages/pymysql/protocol.py", line 219, in raise_for_error
    err.raise_mysql_exception(self._data)
  File "/home/johnatas/nexforce/env/lib/python3.10/site-packages/pymysql/err.py", line 150, in raise_mysql_exception
    raise errorclass(errno, errval)
pymysql.err.OperationalError: (1045, "Access denied for user '_b7ebe10d1e52525e'@'localhost' (using password: YES)")
2025-02-16 21:16:00,706 ERROR scheduler Exception in Enqueue Events for Site commands-site-O4PN2QK.test
Traceback (most recent call last):
  File "/home/johnatas/nexforce/apps/frappe/frappe/utils/scheduler.py", line 105, in enqueue_events_for_site
    if is_scheduler_inactive():
  File "/home/johnatas/nexforce/apps/frappe/frappe/utils/scheduler.py", line 149, in is_scheduler_inactive
    if is_scheduler_disabled(verbose=verbose):
  File "/home/johnatas/nexforce/apps/frappe/frappe/utils/scheduler.py", line 162, in is_scheduler_disabled
    frappe.db.get_single_value("System Settings", "enable_scheduler")
  File "/home/johnatas/nexforce/apps/frappe/frappe/database/database.py", line 869, in get_single_value
    ).run()
  File "/home/johnatas/nexforce/apps/frappe/frappe/query_builder/utils.py", line 84, in execute_query
    result = frappe.db.sql(query, params, *args, **kwargs)  # nosemgrep
  File "/home/johnatas/nexforce/apps/frappe/frappe/database/database.py", line 215, in sql
    self.connect()
  File "/home/johnatas/nexforce/apps/frappe/frappe/database/database.py", line 120, in connect
    self._conn: MariadbConnection | PostgresConnection = self.get_connection()
  File "/home/johnatas/nexforce/apps/frappe/frappe/database/mariadb/database.py", line 107, in get_connection
    conn = self._get_connection()
  File "/home/johnatas/nexforce/apps/frappe/frappe/database/mariadb/database.py", line 113, in _get_connection
    return self.create_connection()
  File "/home/johnatas/nexforce/apps/frappe/frappe/database/mariadb/database.py", line 116, in create_connection
    return pymysql.connect(**self.get_connection_settings())
  File "/home/johnatas/nexforce/env/lib/python3.10/site-packages/pymysql/connections.py", line 361, in __init__
    self.connect()
  File "/home/johnatas/nexforce/env/lib/python3.10/site-packages/pymysql/connections.py", line 669, in connect
    self._request_authentication()
  File "/home/johnatas/nexforce/env/lib/python3.10/site-packages/pymysql/connections.py", line 957, in _request_authentication
    auth_packet = self._read_packet()
  File "/home/johnatas/nexforce/env/lib/python3.10/site-packages/pymysql/connections.py", line 775, in _read_packet
    packet.raise_for_error()
  File "/home/johnatas/nexforce/env/lib/python3.10/site-packages/pymysql/protocol.py", line 219, in raise_for_error
    err.raise_mysql_exception(self._data)
  File "/home/johnatas/nexforce/env/lib/python3.10/site-packages/pymysql/err.py", line 150, in raise_mysql_exception
    raise errorclass(errno, errval)
pymysql.err.OperationalError: (1045, "Access denied for user '_b7ebe10d1e52525e'@'localhost' (using password: YES)")
2025-02-16 21:20:00,355 ERROR scheduler Exception in Enqueue Events for Site commands-site-O4PN2QK.test
Traceback (most recent call last):
  File "/home/johnatas/nexforce/apps/frappe/frappe/utils/scheduler.py", line 105, in enqueue_events_for_site
    if is_scheduler_inactive():
  File "/home/johnatas/nexforce/apps/frappe/frappe/utils/scheduler.py", line 149, in is_scheduler_inactive
    if is_scheduler_disabled(verbose=verbose):
  File "/home/johnatas/nexforce/apps/frappe/frappe/utils/scheduler.py", line 162, in is_scheduler_disabled
    frappe.db.get_single_value("System Settings", "enable_scheduler")
  File "/home/johnatas/nexforce/apps/frappe/frappe/database/database.py", line 869, in get_single_value
    ).run()
  File "/home/johnatas/nexforce/apps/frappe/frappe/query_builder/utils.py", line 84, in execute_query
    result = frappe.db.sql(query, params, *args, **kwargs)  # nosemgrep
  File "/home/johnatas/nexforce/apps/frappe/frappe/database/database.py", line 215, in sql
    self.connect()
  File "/home/johnatas/nexforce/apps/frappe/frappe/database/database.py", line 120, in connect
    self._conn: MariadbConnection | PostgresConnection = self.get_connection()
  File "/home/johnatas/nexforce/apps/frappe/frappe/database/mariadb/database.py", line 107, in get_connection
    conn = self._get_connection()
  File "/home/johnatas/nexforce/apps/frappe/frappe/database/mariadb/database.py", line 113, in _get_connection
    return self.create_connection()
  File "/home/johnatas/nexforce/apps/frappe/frappe/database/mariadb/database.py", line 116, in create_connection
    return pymysql.connect(**self.get_connection_settings())
  File "/home/johnatas/nexforce/env/lib/python3.10/site-packages/pymysql/connections.py", line 361, in __init__
    self.connect()
  File "/home/johnatas/nexforce/env/lib/python3.10/site-packages/pymysql/connections.py", line 669, in connect
    self._request_authentication()
  File "/home/johnatas/nexforce/env/lib/python3.10/site-packages/pymysql/connections.py", line 957, in _request_authentication
    auth_packet = self._read_packet()
  File "/home/johnatas/nexforce/env/lib/python3.10/site-packages/pymysql/connections.py", line 775, in _read_packet
    packet.raise_for_error()
  File "/home/johnatas/nexforce/env/lib/python3.10/site-packages/pymysql/protocol.py", line 219, in raise_for_error
    err.raise_mysql_exception(self._data)
  File "/home/johnatas/nexforce/env/lib/python3.10/site-packages/pymysql/err.py", line 150, in raise_mysql_exception
    raise errorclass(errno, errval)
pymysql.err.OperationalError: (1045, "Access denied for user '_b7ebe10d1e52525e'@'localhost' (using password: YES)")
2025-02-16 21:24:00,440 ERROR scheduler Exception in Enqueue Events for Site commands-site-O4PN2QK.test
Traceback (most recent call last):
  File "/home/johnatas/nexforce/apps/frappe/frappe/utils/scheduler.py", line 105, in enqueue_events_for_site
    if is_scheduler_inactive():
  File "/home/johnatas/nexforce/apps/frappe/frappe/utils/scheduler.py", line 149, in is_scheduler_inactive
    if is_scheduler_disabled(verbose=verbose):
  File "/home/johnatas/nexforce/apps/frappe/frappe/utils/scheduler.py", line 162, in is_scheduler_disabled
    frappe.db.get_single_value("System Settings", "enable_scheduler")
  File "/home/johnatas/nexforce/apps/frappe/frappe/database/database.py", line 869, in get_single_value
    ).run()
  File "/home/johnatas/nexforce/apps/frappe/frappe/query_builder/utils.py", line 84, in execute_query
    result = frappe.db.sql(query, params, *args, **kwargs)  # nosemgrep
  File "/home/johnatas/nexforce/apps/frappe/frappe/database/database.py", line 215, in sql
    self.connect()
  File "/home/johnatas/nexforce/apps/frappe/frappe/database/database.py", line 120, in connect
    self._conn: MariadbConnection | PostgresConnection = self.get_connection()
  File "/home/johnatas/nexforce/apps/frappe/frappe/database/mariadb/database.py", line 107, in get_connection
    conn = self._get_connection()
  File "/home/johnatas/nexforce/apps/frappe/frappe/database/mariadb/database.py", line 113, in _get_connection
    return self.create_connection()
  File "/home/johnatas/nexforce/apps/frappe/frappe/database/mariadb/database.py", line 116, in create_connection
    return pymysql.connect(**self.get_connection_settings())
  File "/home/johnatas/nexforce/env/lib/python3.10/site-packages/pymysql/connections.py", line 361, in __init__
    self.connect()
  File "/home/johnatas/nexforce/env/lib/python3.10/site-packages/pymysql/connections.py", line 669, in connect
    self._request_authentication()
  File "/home/johnatas/nexforce/env/lib/python3.10/site-packages/pymysql/connections.py", line 957, in _request_authentication
    auth_packet = self._read_packet()
  File "/home/johnatas/nexforce/env/lib/python3.10/site-packages/pymysql/connections.py", line 775, in _read_packet
    packet.raise_for_error()
  File "/home/johnatas/nexforce/env/lib/python3.10/site-packages/pymysql/protocol.py", line 219, in raise_for_error
    err.raise_mysql_exception(self._data)
  File "/home/johnatas/nexforce/env/lib/python3.10/site-packages/pymysql/err.py", line 150, in raise_mysql_exception
    raise errorclass(errno, errval)
pymysql.err.OperationalError: (1045, "Access denied for user '_b7ebe10d1e52525e'@'localhost' (using password: YES)")
2025-02-16 21:28:00,764 ERROR scheduler Exception in Enqueue Events for Site commands-site-O4PN2QK.test
Traceback (most recent call last):
  File "/home/johnatas/nexforce/apps/frappe/frappe/utils/scheduler.py", line 105, in enqueue_events_for_site
    if is_scheduler_inactive():
  File "/home/johnatas/nexforce/apps/frappe/frappe/utils/scheduler.py", line 149, in is_scheduler_inactive
    if is_scheduler_disabled(verbose=verbose):
  File "/home/johnatas/nexforce/apps/frappe/frappe/utils/scheduler.py", line 162, in is_scheduler_disabled
    frappe.db.get_single_value("System Settings", "enable_scheduler")
  File "/home/johnatas/nexforce/apps/frappe/frappe/database/database.py", line 869, in get_single_value
    ).run()
  File "/home/johnatas/nexforce/apps/frappe/frappe/query_builder/utils.py", line 84, in execute_query
    result = frappe.db.sql(query, params, *args, **kwargs)  # nosemgrep
  File "/home/johnatas/nexforce/apps/frappe/frappe/database/database.py", line 215, in sql
    self.connect()
  File "/home/johnatas/nexforce/apps/frappe/frappe/database/database.py", line 120, in connect
    self._conn: MariadbConnection | PostgresConnection = self.get_connection()
  File "/home/johnatas/nexforce/apps/frappe/frappe/database/mariadb/database.py", line 107, in get_connection
    conn = self._get_connection()
  File "/home/johnatas/nexforce/apps/frappe/frappe/database/mariadb/database.py", line 113, in _get_connection
    return self.create_connection()
  File "/home/johnatas/nexforce/apps/frappe/frappe/database/mariadb/database.py", line 116, in create_connection
    return pymysql.connect(**self.get_connection_settings())
  File "/home/johnatas/nexforce/env/lib/python3.10/site-packages/pymysql/connections.py", line 361, in __init__
    self.connect()
  File "/home/johnatas/nexforce/env/lib/python3.10/site-packages/pymysql/connections.py", line 669, in connect
    self._request_authentication()
  File "/home/johnatas/nexforce/env/lib/python3.10/site-packages/pymysql/connections.py", line 957, in _request_authentication
    auth_packet = self._read_packet()
  File "/home/johnatas/nexforce/env/lib/python3.10/site-packages/pymysql/connections.py", line 775, in _read_packet
    packet.raise_for_error()
  File "/home/johnatas/nexforce/env/lib/python3.10/site-packages/pymysql/protocol.py", line 219, in raise_for_error
    err.raise_mysql_exception(self._data)
  File "/home/johnatas/nexforce/env/lib/python3.10/site-packages/pymysql/err.py", line 150, in raise_mysql_exception
    raise errorclass(errno, errval)
pymysql.err.OperationalError: (1045, "Access denied for user '_b7ebe10d1e52525e'@'localhost' (using password: YES)")
