2025-02-13 01:16:00,842 ERROR scheduler Exception in Enqueue Events for Site commands-site-O4PN2QK.test
Traceback (most recent call last):
  File "/home/johnatas/nexforce/apps/frappe/frappe/utils/scheduler.py", line 105, in enqueue_events_for_site
    if is_scheduler_inactive():
  File "/home/johnatas/nexforce/apps/frappe/frappe/utils/scheduler.py", line 149, in is_scheduler_inactive
    if is_scheduler_disabled(verbose=verbose):
  File "/home/johnatas/nexforce/apps/frappe/frappe/utils/scheduler.py", line 162, in is_scheduler_disabled
    frappe.db.get_single_value("System Settings", "enable_scheduler")
  File "/home/johnatas/nexforce/apps/frappe/frappe/database/database.py", line 869, in get_single_value
    ).run()
  File "/home/johnatas/nexforce/apps/frappe/frappe/query_builder/utils.py", line 84, in execute_query
    result = frappe.db.sql(query, params, *args, **kwargs)  # nosemgrep
  File "/home/johnatas/nexforce/apps/frappe/frappe/database/database.py", line 215, in sql
    self.connect()
  File "/home/johnatas/nexforce/apps/frappe/frappe/database/database.py", line 120, in connect
    self._conn: MariadbConnection | PostgresConnection = self.get_connection()
  File "/home/johnatas/nexforce/apps/frappe/frappe/database/mariadb/database.py", line 107, in get_connection
    conn = self._get_connection()
  File "/home/johnatas/nexforce/apps/frappe/frappe/database/mariadb/database.py", line 113, in _get_connection
    return self.create_connection()
  File "/home/johnatas/nexforce/apps/frappe/frappe/database/mariadb/database.py", line 116, in create_connection
    return pymysql.connect(**self.get_connection_settings())
  File "/home/johnatas/nexforce/env/lib/python3.10/site-packages/pymysql/connections.py", line 361, in __init__
    self.connect()
  File "/home/johnatas/nexforce/env/lib/python3.10/site-packages/pymysql/connections.py", line 669, in connect
    self._request_authentication()
  File "/home/johnatas/nexforce/env/lib/python3.10/site-packages/pymysql/connections.py", line 957, in _request_authentication
    auth_packet = self._read_packet()
  File "/home/johnatas/nexforce/env/lib/python3.10/site-packages/pymysql/connections.py", line 775, in _read_packet
    packet.raise_for_error()
  File "/home/johnatas/nexforce/env/lib/python3.10/site-packages/pymysql/protocol.py", line 219, in raise_for_error
    err.raise_mysql_exception(self._data)
  File "/home/johnatas/nexforce/env/lib/python3.10/site-packages/pymysql/err.py", line 150, in raise_mysql_exception
    raise errorclass(errno, errval)
pymysql.err.OperationalError: (1045, "Access denied for user '_b7ebe10d1e52525e'@'localhost' (using password: YES)")
2025-02-13 01:20:01,116 ERROR scheduler Exception in Enqueue Events for Site commands-site-O4PN2QK.test
Traceback (most recent call last):
  File "/home/johnatas/nexforce/apps/frappe/frappe/utils/scheduler.py", line 105, in enqueue_events_for_site
    if is_scheduler_inactive():
  File "/home/johnatas/nexforce/apps/frappe/frappe/utils/scheduler.py", line 149, in is_scheduler_inactive
    if is_scheduler_disabled(verbose=verbose):
  File "/home/johnatas/nexforce/apps/frappe/frappe/utils/scheduler.py", line 162, in is_scheduler_disabled
    frappe.db.get_single_value("System Settings", "enable_scheduler")
  File "/home/johnatas/nexforce/apps/frappe/frappe/database/database.py", line 869, in get_single_value
    ).run()
  File "/home/johnatas/nexforce/apps/frappe/frappe/query_builder/utils.py", line 84, in execute_query
    result = frappe.db.sql(query, params, *args, **kwargs)  # nosemgrep
  File "/home/johnatas/nexforce/apps/frappe/frappe/database/database.py", line 215, in sql
    self.connect()
  File "/home/johnatas/nexforce/apps/frappe/frappe/database/database.py", line 120, in connect
    self._conn: MariadbConnection | PostgresConnection = self.get_connection()
  File "/home/johnatas/nexforce/apps/frappe/frappe/database/mariadb/database.py", line 107, in get_connection
    conn = self._get_connection()
  File "/home/johnatas/nexforce/apps/frappe/frappe/database/mariadb/database.py", line 113, in _get_connection
    return self.create_connection()
  File "/home/johnatas/nexforce/apps/frappe/frappe/database/mariadb/database.py", line 116, in create_connection
    return pymysql.connect(**self.get_connection_settings())
  File "/home/johnatas/nexforce/env/lib/python3.10/site-packages/pymysql/connections.py", line 361, in __init__
    self.connect()
  File "/home/johnatas/nexforce/env/lib/python3.10/site-packages/pymysql/connections.py", line 669, in connect
    self._request_authentication()
  File "/home/johnatas/nexforce/env/lib/python3.10/site-packages/pymysql/connections.py", line 957, in _request_authentication
    auth_packet = self._read_packet()
  File "/home/johnatas/nexforce/env/lib/python3.10/site-packages/pymysql/connections.py", line 775, in _read_packet
    packet.raise_for_error()
  File "/home/johnatas/nexforce/env/lib/python3.10/site-packages/pymysql/protocol.py", line 219, in raise_for_error
    err.raise_mysql_exception(self._data)
  File "/home/johnatas/nexforce/env/lib/python3.10/site-packages/pymysql/err.py", line 150, in raise_mysql_exception
    raise errorclass(errno, errval)
pymysql.err.OperationalError: (1045, "Access denied for user '_b7ebe10d1e52525e'@'localhost' (using password: YES)")
2025-02-13 01:24:00,277 ERROR scheduler Exception in Enqueue Events for Site commands-site-O4PN2QK.test
Traceback (most recent call last):
  File "/home/johnatas/nexforce/apps/frappe/frappe/utils/scheduler.py", line 105, in enqueue_events_for_site
    if is_scheduler_inactive():
  File "/home/johnatas/nexforce/apps/frappe/frappe/utils/scheduler.py", line 149, in is_scheduler_inactive
    if is_scheduler_disabled(verbose=verbose):
  File "/home/johnatas/nexforce/apps/frappe/frappe/utils/scheduler.py", line 162, in is_scheduler_disabled
    frappe.db.get_single_value("System Settings", "enable_scheduler")
  File "/home/johnatas/nexforce/apps/frappe/frappe/database/database.py", line 869, in get_single_value
    ).run()
  File "/home/johnatas/nexforce/apps/frappe/frappe/query_builder/utils.py", line 84, in execute_query
    result = frappe.db.sql(query, params, *args, **kwargs)  # nosemgrep
  File "/home/johnatas/nexforce/apps/frappe/frappe/database/database.py", line 215, in sql
    self.connect()
  File "/home/johnatas/nexforce/apps/frappe/frappe/database/database.py", line 120, in connect
    self._conn: MariadbConnection | PostgresConnection = self.get_connection()
  File "/home/johnatas/nexforce/apps/frappe/frappe/database/mariadb/database.py", line 107, in get_connection
    conn = self._get_connection()
  File "/home/johnatas/nexforce/apps/frappe/frappe/database/mariadb/database.py", line 113, in _get_connection
    return self.create_connection()
  File "/home/johnatas/nexforce/apps/frappe/frappe/database/mariadb/database.py", line 116, in create_connection
    return pymysql.connect(**self.get_connection_settings())
  File "/home/johnatas/nexforce/env/lib/python3.10/site-packages/pymysql/connections.py", line 361, in __init__
    self.connect()
  File "/home/johnatas/nexforce/env/lib/python3.10/site-packages/pymysql/connections.py", line 669, in connect
    self._request_authentication()
  File "/home/johnatas/nexforce/env/lib/python3.10/site-packages/pymysql/connections.py", line 957, in _request_authentication
    auth_packet = self._read_packet()
  File "/home/johnatas/nexforce/env/lib/python3.10/site-packages/pymysql/connections.py", line 775, in _read_packet
    packet.raise_for_error()
  File "/home/johnatas/nexforce/env/lib/python3.10/site-packages/pymysql/protocol.py", line 219, in raise_for_error
    err.raise_mysql_exception(self._data)
  File "/home/johnatas/nexforce/env/lib/python3.10/site-packages/pymysql/err.py", line 150, in raise_mysql_exception
    raise errorclass(errno, errval)
pymysql.err.OperationalError: (1045, "Access denied for user '_b7ebe10d1e52525e'@'localhost' (using password: YES)")
2025-02-13 01:28:00,380 ERROR scheduler Exception in Enqueue Events for Site commands-site-O4PN2QK.test
Traceback (most recent call last):
  File "/home/johnatas/nexforce/apps/frappe/frappe/utils/scheduler.py", line 105, in enqueue_events_for_site
    if is_scheduler_inactive():
  File "/home/johnatas/nexforce/apps/frappe/frappe/utils/scheduler.py", line 149, in is_scheduler_inactive
    if is_scheduler_disabled(verbose=verbose):
  File "/home/johnatas/nexforce/apps/frappe/frappe/utils/scheduler.py", line 162, in is_scheduler_disabled
    frappe.db.get_single_value("System Settings", "enable_scheduler")
  File "/home/johnatas/nexforce/apps/frappe/frappe/database/database.py", line 869, in get_single_value
    ).run()
  File "/home/johnatas/nexforce/apps/frappe/frappe/query_builder/utils.py", line 84, in execute_query
    result = frappe.db.sql(query, params, *args, **kwargs)  # nosemgrep
  File "/home/johnatas/nexforce/apps/frappe/frappe/database/database.py", line 215, in sql
    self.connect()
  File "/home/johnatas/nexforce/apps/frappe/frappe/database/database.py", line 120, in connect
    self._conn: MariadbConnection | PostgresConnection = self.get_connection()
  File "/home/johnatas/nexforce/apps/frappe/frappe/database/mariadb/database.py", line 107, in get_connection
    conn = self._get_connection()
  File "/home/johnatas/nexforce/apps/frappe/frappe/database/mariadb/database.py", line 113, in _get_connection
    return self.create_connection()
  File "/home/johnatas/nexforce/apps/frappe/frappe/database/mariadb/database.py", line 116, in create_connection
    return pymysql.connect(**self.get_connection_settings())
  File "/home/johnatas/nexforce/env/lib/python3.10/site-packages/pymysql/connections.py", line 361, in __init__
    self.connect()
  File "/home/johnatas/nexforce/env/lib/python3.10/site-packages/pymysql/connections.py", line 669, in connect
    self._request_authentication()
  File "/home/johnatas/nexforce/env/lib/python3.10/site-packages/pymysql/connections.py", line 957, in _request_authentication
    auth_packet = self._read_packet()
  File "/home/johnatas/nexforce/env/lib/python3.10/site-packages/pymysql/connections.py", line 775, in _read_packet
    packet.raise_for_error()
  File "/home/johnatas/nexforce/env/lib/python3.10/site-packages/pymysql/protocol.py", line 219, in raise_for_error
    err.raise_mysql_exception(self._data)
  File "/home/johnatas/nexforce/env/lib/python3.10/site-packages/pymysql/err.py", line 150, in raise_mysql_exception
    raise errorclass(errno, errval)
pymysql.err.OperationalError: (1045, "Access denied for user '_b7ebe10d1e52525e'@'localhost' (using password: YES)")
2025-02-13 01:32:00,704 ERROR scheduler Exception in Enqueue Events for Site commands-site-O4PN2QK.test
Traceback (most recent call last):
  File "/home/johnatas/nexforce/apps/frappe/frappe/utils/scheduler.py", line 105, in enqueue_events_for_site
    if is_scheduler_inactive():
  File "/home/johnatas/nexforce/apps/frappe/frappe/utils/scheduler.py", line 149, in is_scheduler_inactive
    if is_scheduler_disabled(verbose=verbose):
  File "/home/johnatas/nexforce/apps/frappe/frappe/utils/scheduler.py", line 162, in is_scheduler_disabled
    frappe.db.get_single_value("System Settings", "enable_scheduler")
  File "/home/johnatas/nexforce/apps/frappe/frappe/database/database.py", line 869, in get_single_value
    ).run()
  File "/home/johnatas/nexforce/apps/frappe/frappe/query_builder/utils.py", line 84, in execute_query
    result = frappe.db.sql(query, params, *args, **kwargs)  # nosemgrep
  File "/home/johnatas/nexforce/apps/frappe/frappe/database/database.py", line 215, in sql
    self.connect()
  File "/home/johnatas/nexforce/apps/frappe/frappe/database/database.py", line 120, in connect
    self._conn: MariadbConnection | PostgresConnection = self.get_connection()
  File "/home/johnatas/nexforce/apps/frappe/frappe/database/mariadb/database.py", line 107, in get_connection
    conn = self._get_connection()
  File "/home/johnatas/nexforce/apps/frappe/frappe/database/mariadb/database.py", line 113, in _get_connection
    return self.create_connection()
  File "/home/johnatas/nexforce/apps/frappe/frappe/database/mariadb/database.py", line 116, in create_connection
    return pymysql.connect(**self.get_connection_settings())
  File "/home/johnatas/nexforce/env/lib/python3.10/site-packages/pymysql/connections.py", line 361, in __init__
    self.connect()
  File "/home/johnatas/nexforce/env/lib/python3.10/site-packages/pymysql/connections.py", line 669, in connect
    self._request_authentication()
  File "/home/johnatas/nexforce/env/lib/python3.10/site-packages/pymysql/connections.py", line 957, in _request_authentication
    auth_packet = self._read_packet()
  File "/home/johnatas/nexforce/env/lib/python3.10/site-packages/pymysql/connections.py", line 775, in _read_packet
    packet.raise_for_error()
  File "/home/johnatas/nexforce/env/lib/python3.10/site-packages/pymysql/protocol.py", line 219, in raise_for_error
    err.raise_mysql_exception(self._data)
  File "/home/johnatas/nexforce/env/lib/python3.10/site-packages/pymysql/err.py", line 150, in raise_mysql_exception
    raise errorclass(errno, errval)
pymysql.err.OperationalError: (1045, "Access denied for user '_b7ebe10d1e52525e'@'localhost' (using password: YES)")
2025-02-13 01:36:01,011 ERROR scheduler Exception in Enqueue Events for Site commands-site-O4PN2QK.test
Traceback (most recent call last):
  File "/home/johnatas/nexforce/apps/frappe/frappe/utils/scheduler.py", line 105, in enqueue_events_for_site
    if is_scheduler_inactive():
  File "/home/johnatas/nexforce/apps/frappe/frappe/utils/scheduler.py", line 149, in is_scheduler_inactive
    if is_scheduler_disabled(verbose=verbose):
  File "/home/johnatas/nexforce/apps/frappe/frappe/utils/scheduler.py", line 162, in is_scheduler_disabled
    frappe.db.get_single_value("System Settings", "enable_scheduler")
  File "/home/johnatas/nexforce/apps/frappe/frappe/database/database.py", line 869, in get_single_value
    ).run()
  File "/home/johnatas/nexforce/apps/frappe/frappe/query_builder/utils.py", line 84, in execute_query
    result = frappe.db.sql(query, params, *args, **kwargs)  # nosemgrep
  File "/home/johnatas/nexforce/apps/frappe/frappe/database/database.py", line 215, in sql
    self.connect()
  File "/home/johnatas/nexforce/apps/frappe/frappe/database/database.py", line 120, in connect
    self._conn: MariadbConnection | PostgresConnection = self.get_connection()
  File "/home/johnatas/nexforce/apps/frappe/frappe/database/mariadb/database.py", line 107, in get_connection
    conn = self._get_connection()
  File "/home/johnatas/nexforce/apps/frappe/frappe/database/mariadb/database.py", line 113, in _get_connection
    return self.create_connection()
  File "/home/johnatas/nexforce/apps/frappe/frappe/database/mariadb/database.py", line 116, in create_connection
    return pymysql.connect(**self.get_connection_settings())
  File "/home/johnatas/nexforce/env/lib/python3.10/site-packages/pymysql/connections.py", line 361, in __init__
    self.connect()
  File "/home/johnatas/nexforce/env/lib/python3.10/site-packages/pymysql/connections.py", line 669, in connect
    self._request_authentication()
  File "/home/johnatas/nexforce/env/lib/python3.10/site-packages/pymysql/connections.py", line 957, in _request_authentication
    auth_packet = self._read_packet()
  File "/home/johnatas/nexforce/env/lib/python3.10/site-packages/pymysql/connections.py", line 775, in _read_packet
    packet.raise_for_error()
  File "/home/johnatas/nexforce/env/lib/python3.10/site-packages/pymysql/protocol.py", line 219, in raise_for_error
    err.raise_mysql_exception(self._data)
  File "/home/johnatas/nexforce/env/lib/python3.10/site-packages/pymysql/err.py", line 150, in raise_mysql_exception
    raise errorclass(errno, errval)
pymysql.err.OperationalError: (1045, "Access denied for user '_b7ebe10d1e52525e'@'localhost' (using password: YES)")
2025-02-13 01:40:00,213 ERROR scheduler Exception in Enqueue Events for Site commands-site-O4PN2QK.test
Traceback (most recent call last):
  File "/home/johnatas/nexforce/apps/frappe/frappe/utils/scheduler.py", line 105, in enqueue_events_for_site
    if is_scheduler_inactive():
  File "/home/johnatas/nexforce/apps/frappe/frappe/utils/scheduler.py", line 149, in is_scheduler_inactive
    if is_scheduler_disabled(verbose=verbose):
  File "/home/johnatas/nexforce/apps/frappe/frappe/utils/scheduler.py", line 162, in is_scheduler_disabled
    frappe.db.get_single_value("System Settings", "enable_scheduler")
  File "/home/johnatas/nexforce/apps/frappe/frappe/database/database.py", line 869, in get_single_value
    ).run()
  File "/home/johnatas/nexforce/apps/frappe/frappe/query_builder/utils.py", line 84, in execute_query
    result = frappe.db.sql(query, params, *args, **kwargs)  # nosemgrep
  File "/home/johnatas/nexforce/apps/frappe/frappe/database/database.py", line 215, in sql
    self.connect()
  File "/home/johnatas/nexforce/apps/frappe/frappe/database/database.py", line 120, in connect
    self._conn: MariadbConnection | PostgresConnection = self.get_connection()
  File "/home/johnatas/nexforce/apps/frappe/frappe/database/mariadb/database.py", line 107, in get_connection
    conn = self._get_connection()
  File "/home/johnatas/nexforce/apps/frappe/frappe/database/mariadb/database.py", line 113, in _get_connection
    return self.create_connection()
  File "/home/johnatas/nexforce/apps/frappe/frappe/database/mariadb/database.py", line 116, in create_connection
    return pymysql.connect(**self.get_connection_settings())
  File "/home/johnatas/nexforce/env/lib/python3.10/site-packages/pymysql/connections.py", line 361, in __init__
    self.connect()
  File "/home/johnatas/nexforce/env/lib/python3.10/site-packages/pymysql/connections.py", line 669, in connect
    self._request_authentication()
  File "/home/johnatas/nexforce/env/lib/python3.10/site-packages/pymysql/connections.py", line 957, in _request_authentication
    auth_packet = self._read_packet()
  File "/home/johnatas/nexforce/env/lib/python3.10/site-packages/pymysql/connections.py", line 775, in _read_packet
    packet.raise_for_error()
  File "/home/johnatas/nexforce/env/lib/python3.10/site-packages/pymysql/protocol.py", line 219, in raise_for_error
    err.raise_mysql_exception(self._data)
  File "/home/johnatas/nexforce/env/lib/python3.10/site-packages/pymysql/err.py", line 150, in raise_mysql_exception
    raise errorclass(errno, errval)
pymysql.err.OperationalError: (1045, "Access denied for user '_b7ebe10d1e52525e'@'localhost' (using password: YES)")
2025-02-13 01:44:00,486 ERROR scheduler Exception in Enqueue Events for Site commands-site-O4PN2QK.test
Traceback (most recent call last):
  File "/home/johnatas/nexforce/apps/frappe/frappe/utils/scheduler.py", line 105, in enqueue_events_for_site
    if is_scheduler_inactive():
  File "/home/johnatas/nexforce/apps/frappe/frappe/utils/scheduler.py", line 149, in is_scheduler_inactive
    if is_scheduler_disabled(verbose=verbose):
  File "/home/johnatas/nexforce/apps/frappe/frappe/utils/scheduler.py", line 162, in is_scheduler_disabled
    frappe.db.get_single_value("System Settings", "enable_scheduler")
  File "/home/johnatas/nexforce/apps/frappe/frappe/database/database.py", line 869, in get_single_value
    ).run()
  File "/home/johnatas/nexforce/apps/frappe/frappe/query_builder/utils.py", line 84, in execute_query
    result = frappe.db.sql(query, params, *args, **kwargs)  # nosemgrep
  File "/home/johnatas/nexforce/apps/frappe/frappe/database/database.py", line 215, in sql
    self.connect()
  File "/home/johnatas/nexforce/apps/frappe/frappe/database/database.py", line 120, in connect
    self._conn: MariadbConnection | PostgresConnection = self.get_connection()
  File "/home/johnatas/nexforce/apps/frappe/frappe/database/mariadb/database.py", line 107, in get_connection
    conn = self._get_connection()
  File "/home/johnatas/nexforce/apps/frappe/frappe/database/mariadb/database.py", line 113, in _get_connection
    return self.create_connection()
  File "/home/johnatas/nexforce/apps/frappe/frappe/database/mariadb/database.py", line 116, in create_connection
    return pymysql.connect(**self.get_connection_settings())
  File "/home/johnatas/nexforce/env/lib/python3.10/site-packages/pymysql/connections.py", line 361, in __init__
    self.connect()
  File "/home/johnatas/nexforce/env/lib/python3.10/site-packages/pymysql/connections.py", line 669, in connect
    self._request_authentication()
  File "/home/johnatas/nexforce/env/lib/python3.10/site-packages/pymysql/connections.py", line 957, in _request_authentication
    auth_packet = self._read_packet()
  File "/home/johnatas/nexforce/env/lib/python3.10/site-packages/pymysql/connections.py", line 775, in _read_packet
    packet.raise_for_error()
  File "/home/johnatas/nexforce/env/lib/python3.10/site-packages/pymysql/protocol.py", line 219, in raise_for_error
    err.raise_mysql_exception(self._data)
  File "/home/johnatas/nexforce/env/lib/python3.10/site-packages/pymysql/err.py", line 150, in raise_mysql_exception
    raise errorclass(errno, errval)
pymysql.err.OperationalError: (1045, "Access denied for user '_b7ebe10d1e52525e'@'localhost' (using password: YES)")
2025-02-13 01:48:00,762 ERROR scheduler Exception in Enqueue Events for Site commands-site-O4PN2QK.test
Traceback (most recent call last):
  File "/home/johnatas/nexforce/apps/frappe/frappe/utils/scheduler.py", line 105, in enqueue_events_for_site
    if is_scheduler_inactive():
  File "/home/johnatas/nexforce/apps/frappe/frappe/utils/scheduler.py", line 149, in is_scheduler_inactive
    if is_scheduler_disabled(verbose=verbose):
  File "/home/johnatas/nexforce/apps/frappe/frappe/utils/scheduler.py", line 162, in is_scheduler_disabled
    frappe.db.get_single_value("System Settings", "enable_scheduler")
  File "/home/johnatas/nexforce/apps/frappe/frappe/database/database.py", line 869, in get_single_value
    ).run()
  File "/home/johnatas/nexforce/apps/frappe/frappe/query_builder/utils.py", line 84, in execute_query
    result = frappe.db.sql(query, params, *args, **kwargs)  # nosemgrep
  File "/home/johnatas/nexforce/apps/frappe/frappe/database/database.py", line 215, in sql
    self.connect()
  File "/home/johnatas/nexforce/apps/frappe/frappe/database/database.py", line 120, in connect
    self._conn: MariadbConnection | PostgresConnection = self.get_connection()
  File "/home/johnatas/nexforce/apps/frappe/frappe/database/mariadb/database.py", line 107, in get_connection
    conn = self._get_connection()
  File "/home/johnatas/nexforce/apps/frappe/frappe/database/mariadb/database.py", line 113, in _get_connection
    return self.create_connection()
  File "/home/johnatas/nexforce/apps/frappe/frappe/database/mariadb/database.py", line 116, in create_connection
    return pymysql.connect(**self.get_connection_settings())
  File "/home/johnatas/nexforce/env/lib/python3.10/site-packages/pymysql/connections.py", line 361, in __init__
    self.connect()
  File "/home/johnatas/nexforce/env/lib/python3.10/site-packages/pymysql/connections.py", line 669, in connect
    self._request_authentication()
  File "/home/johnatas/nexforce/env/lib/python3.10/site-packages/pymysql/connections.py", line 957, in _request_authentication
    auth_packet = self._read_packet()
  File "/home/johnatas/nexforce/env/lib/python3.10/site-packages/pymysql/connections.py", line 775, in _read_packet
    packet.raise_for_error()
  File "/home/johnatas/nexforce/env/lib/python3.10/site-packages/pymysql/protocol.py", line 219, in raise_for_error
    err.raise_mysql_exception(self._data)
  File "/home/johnatas/nexforce/env/lib/python3.10/site-packages/pymysql/err.py", line 150, in raise_mysql_exception
    raise errorclass(errno, errval)
pymysql.err.OperationalError: (1045, "Access denied for user '_b7ebe10d1e52525e'@'localhost' (using password: YES)")
2025-02-13 01:52:01,048 ERROR scheduler Exception in Enqueue Events for Site commands-site-O4PN2QK.test
Traceback (most recent call last):
  File "/home/johnatas/nexforce/apps/frappe/frappe/utils/scheduler.py", line 105, in enqueue_events_for_site
    if is_scheduler_inactive():
  File "/home/johnatas/nexforce/apps/frappe/frappe/utils/scheduler.py", line 149, in is_scheduler_inactive
    if is_scheduler_disabled(verbose=verbose):
  File "/home/johnatas/nexforce/apps/frappe/frappe/utils/scheduler.py", line 162, in is_scheduler_disabled
    frappe.db.get_single_value("System Settings", "enable_scheduler")
  File "/home/johnatas/nexforce/apps/frappe/frappe/database/database.py", line 869, in get_single_value
    ).run()
  File "/home/johnatas/nexforce/apps/frappe/frappe/query_builder/utils.py", line 84, in execute_query
    result = frappe.db.sql(query, params, *args, **kwargs)  # nosemgrep
  File "/home/johnatas/nexforce/apps/frappe/frappe/database/database.py", line 215, in sql
    self.connect()
  File "/home/johnatas/nexforce/apps/frappe/frappe/database/database.py", line 120, in connect
    self._conn: MariadbConnection | PostgresConnection = self.get_connection()
  File "/home/johnatas/nexforce/apps/frappe/frappe/database/mariadb/database.py", line 107, in get_connection
    conn = self._get_connection()
  File "/home/johnatas/nexforce/apps/frappe/frappe/database/mariadb/database.py", line 113, in _get_connection
    return self.create_connection()
  File "/home/johnatas/nexforce/apps/frappe/frappe/database/mariadb/database.py", line 116, in create_connection
    return pymysql.connect(**self.get_connection_settings())
  File "/home/johnatas/nexforce/env/lib/python3.10/site-packages/pymysql/connections.py", line 361, in __init__
    self.connect()
  File "/home/johnatas/nexforce/env/lib/python3.10/site-packages/pymysql/connections.py", line 669, in connect
    self._request_authentication()
  File "/home/johnatas/nexforce/env/lib/python3.10/site-packages/pymysql/connections.py", line 957, in _request_authentication
    auth_packet = self._read_packet()
  File "/home/johnatas/nexforce/env/lib/python3.10/site-packages/pymysql/connections.py", line 775, in _read_packet
    packet.raise_for_error()
  File "/home/johnatas/nexforce/env/lib/python3.10/site-packages/pymysql/protocol.py", line 219, in raise_for_error
    err.raise_mysql_exception(self._data)
  File "/home/johnatas/nexforce/env/lib/python3.10/site-packages/pymysql/err.py", line 150, in raise_mysql_exception
    raise errorclass(errno, errval)
pymysql.err.OperationalError: (1045, "Access denied for user '_b7ebe10d1e52525e'@'localhost' (using password: YES)")
2025-02-13 01:56:00,063 ERROR scheduler Exception in Enqueue Events for Site commands-site-O4PN2QK.test
Traceback (most recent call last):
  File "/home/johnatas/nexforce/apps/frappe/frappe/utils/scheduler.py", line 105, in enqueue_events_for_site
    if is_scheduler_inactive():
  File "/home/johnatas/nexforce/apps/frappe/frappe/utils/scheduler.py", line 149, in is_scheduler_inactive
    if is_scheduler_disabled(verbose=verbose):
  File "/home/johnatas/nexforce/apps/frappe/frappe/utils/scheduler.py", line 162, in is_scheduler_disabled
    frappe.db.get_single_value("System Settings", "enable_scheduler")
  File "/home/johnatas/nexforce/apps/frappe/frappe/database/database.py", line 869, in get_single_value
    ).run()
  File "/home/johnatas/nexforce/apps/frappe/frappe/query_builder/utils.py", line 84, in execute_query
    result = frappe.db.sql(query, params, *args, **kwargs)  # nosemgrep
  File "/home/johnatas/nexforce/apps/frappe/frappe/database/database.py", line 215, in sql
    self.connect()
  File "/home/johnatas/nexforce/apps/frappe/frappe/database/database.py", line 120, in connect
    self._conn: MariadbConnection | PostgresConnection = self.get_connection()
  File "/home/johnatas/nexforce/apps/frappe/frappe/database/mariadb/database.py", line 107, in get_connection
    conn = self._get_connection()
  File "/home/johnatas/nexforce/apps/frappe/frappe/database/mariadb/database.py", line 113, in _get_connection
    return self.create_connection()
  File "/home/johnatas/nexforce/apps/frappe/frappe/database/mariadb/database.py", line 116, in create_connection
    return pymysql.connect(**self.get_connection_settings())
  File "/home/johnatas/nexforce/env/lib/python3.10/site-packages/pymysql/connections.py", line 361, in __init__
    self.connect()
  File "/home/johnatas/nexforce/env/lib/python3.10/site-packages/pymysql/connections.py", line 669, in connect
    self._request_authentication()
  File "/home/johnatas/nexforce/env/lib/python3.10/site-packages/pymysql/connections.py", line 957, in _request_authentication
    auth_packet = self._read_packet()
  File "/home/johnatas/nexforce/env/lib/python3.10/site-packages/pymysql/connections.py", line 775, in _read_packet
    packet.raise_for_error()
  File "/home/johnatas/nexforce/env/lib/python3.10/site-packages/pymysql/protocol.py", line 219, in raise_for_error
    err.raise_mysql_exception(self._data)
  File "/home/johnatas/nexforce/env/lib/python3.10/site-packages/pymysql/err.py", line 150, in raise_mysql_exception
    raise errorclass(errno, errval)
pymysql.err.OperationalError: (1045, "Access denied for user '_b7ebe10d1e52525e'@'localhost' (using password: YES)")
2025-02-13 02:00:00,329 ERROR scheduler Exception in Enqueue Events for Site commands-site-O4PN2QK.test
Traceback (most recent call last):
  File "/home/johnatas/nexforce/apps/frappe/frappe/utils/scheduler.py", line 105, in enqueue_events_for_site
    if is_scheduler_inactive():
  File "/home/johnatas/nexforce/apps/frappe/frappe/utils/scheduler.py", line 149, in is_scheduler_inactive
    if is_scheduler_disabled(verbose=verbose):
  File "/home/johnatas/nexforce/apps/frappe/frappe/utils/scheduler.py", line 162, in is_scheduler_disabled
    frappe.db.get_single_value("System Settings", "enable_scheduler")
  File "/home/johnatas/nexforce/apps/frappe/frappe/database/database.py", line 869, in get_single_value
    ).run()
  File "/home/johnatas/nexforce/apps/frappe/frappe/query_builder/utils.py", line 84, in execute_query
    result = frappe.db.sql(query, params, *args, **kwargs)  # nosemgrep
  File "/home/johnatas/nexforce/apps/frappe/frappe/database/database.py", line 215, in sql
    self.connect()
  File "/home/johnatas/nexforce/apps/frappe/frappe/database/database.py", line 120, in connect
    self._conn: MariadbConnection | PostgresConnection = self.get_connection()
  File "/home/johnatas/nexforce/apps/frappe/frappe/database/mariadb/database.py", line 107, in get_connection
    conn = self._get_connection()
  File "/home/johnatas/nexforce/apps/frappe/frappe/database/mariadb/database.py", line 113, in _get_connection
    return self.create_connection()
  File "/home/johnatas/nexforce/apps/frappe/frappe/database/mariadb/database.py", line 116, in create_connection
    return pymysql.connect(**self.get_connection_settings())
  File "/home/johnatas/nexforce/env/lib/python3.10/site-packages/pymysql/connections.py", line 361, in __init__
    self.connect()
  File "/home/johnatas/nexforce/env/lib/python3.10/site-packages/pymysql/connections.py", line 669, in connect
    self._request_authentication()
  File "/home/johnatas/nexforce/env/lib/python3.10/site-packages/pymysql/connections.py", line 957, in _request_authentication
    auth_packet = self._read_packet()
  File "/home/johnatas/nexforce/env/lib/python3.10/site-packages/pymysql/connections.py", line 775, in _read_packet
    packet.raise_for_error()
  File "/home/johnatas/nexforce/env/lib/python3.10/site-packages/pymysql/protocol.py", line 219, in raise_for_error
    err.raise_mysql_exception(self._data)
  File "/home/johnatas/nexforce/env/lib/python3.10/site-packages/pymysql/err.py", line 150, in raise_mysql_exception
    raise errorclass(errno, errval)
pymysql.err.OperationalError: (1045, "Access denied for user '_b7ebe10d1e52525e'@'localhost' (using password: YES)")
2025-02-13 02:04:00,753 ERROR scheduler Exception in Enqueue Events for Site commands-site-O4PN2QK.test
Traceback (most recent call last):
  File "/home/johnatas/nexforce/apps/frappe/frappe/utils/scheduler.py", line 105, in enqueue_events_for_site
    if is_scheduler_inactive():
  File "/home/johnatas/nexforce/apps/frappe/frappe/utils/scheduler.py", line 149, in is_scheduler_inactive
    if is_scheduler_disabled(verbose=verbose):
  File "/home/johnatas/nexforce/apps/frappe/frappe/utils/scheduler.py", line 162, in is_scheduler_disabled
    frappe.db.get_single_value("System Settings", "enable_scheduler")
  File "/home/johnatas/nexforce/apps/frappe/frappe/database/database.py", line 869, in get_single_value
    ).run()
  File "/home/johnatas/nexforce/apps/frappe/frappe/query_builder/utils.py", line 84, in execute_query
    result = frappe.db.sql(query, params, *args, **kwargs)  # nosemgrep
  File "/home/johnatas/nexforce/apps/frappe/frappe/database/database.py", line 215, in sql
    self.connect()
  File "/home/johnatas/nexforce/apps/frappe/frappe/database/database.py", line 120, in connect
    self._conn: MariadbConnection | PostgresConnection = self.get_connection()
  File "/home/johnatas/nexforce/apps/frappe/frappe/database/mariadb/database.py", line 107, in get_connection
    conn = self._get_connection()
  File "/home/johnatas/nexforce/apps/frappe/frappe/database/mariadb/database.py", line 113, in _get_connection
    return self.create_connection()
  File "/home/johnatas/nexforce/apps/frappe/frappe/database/mariadb/database.py", line 116, in create_connection
    return pymysql.connect(**self.get_connection_settings())
  File "/home/johnatas/nexforce/env/lib/python3.10/site-packages/pymysql/connections.py", line 361, in __init__
    self.connect()
  File "/home/johnatas/nexforce/env/lib/python3.10/site-packages/pymysql/connections.py", line 669, in connect
    self._request_authentication()
  File "/home/johnatas/nexforce/env/lib/python3.10/site-packages/pymysql/connections.py", line 957, in _request_authentication
    auth_packet = self._read_packet()
  File "/home/johnatas/nexforce/env/lib/python3.10/site-packages/pymysql/connections.py", line 775, in _read_packet
    packet.raise_for_error()
  File "/home/johnatas/nexforce/env/lib/python3.10/site-packages/pymysql/protocol.py", line 219, in raise_for_error
    err.raise_mysql_exception(self._data)
  File "/home/johnatas/nexforce/env/lib/python3.10/site-packages/pymysql/err.py", line 150, in raise_mysql_exception
    raise errorclass(errno, errval)
pymysql.err.OperationalError: (1045, "Access denied for user '_b7ebe10d1e52525e'@'localhost' (using password: YES)")
2025-02-13 02:08:01,043 ERROR scheduler Exception in Enqueue Events for Site commands-site-O4PN2QK.test
Traceback (most recent call last):
  File "/home/johnatas/nexforce/apps/frappe/frappe/utils/scheduler.py", line 105, in enqueue_events_for_site
    if is_scheduler_inactive():
  File "/home/johnatas/nexforce/apps/frappe/frappe/utils/scheduler.py", line 149, in is_scheduler_inactive
    if is_scheduler_disabled(verbose=verbose):
  File "/home/johnatas/nexforce/apps/frappe/frappe/utils/scheduler.py", line 162, in is_scheduler_disabled
    frappe.db.get_single_value("System Settings", "enable_scheduler")
  File "/home/johnatas/nexforce/apps/frappe/frappe/database/database.py", line 869, in get_single_value
    ).run()
  File "/home/johnatas/nexforce/apps/frappe/frappe/query_builder/utils.py", line 84, in execute_query
    result = frappe.db.sql(query, params, *args, **kwargs)  # nosemgrep
  File "/home/johnatas/nexforce/apps/frappe/frappe/database/database.py", line 215, in sql
    self.connect()
  File "/home/johnatas/nexforce/apps/frappe/frappe/database/database.py", line 120, in connect
    self._conn: MariadbConnection | PostgresConnection = self.get_connection()
  File "/home/johnatas/nexforce/apps/frappe/frappe/database/mariadb/database.py", line 107, in get_connection
    conn = self._get_connection()
  File "/home/johnatas/nexforce/apps/frappe/frappe/database/mariadb/database.py", line 113, in _get_connection
    return self.create_connection()
  File "/home/johnatas/nexforce/apps/frappe/frappe/database/mariadb/database.py", line 116, in create_connection
    return pymysql.connect(**self.get_connection_settings())
  File "/home/johnatas/nexforce/env/lib/python3.10/site-packages/pymysql/connections.py", line 361, in __init__
    self.connect()
  File "/home/johnatas/nexforce/env/lib/python3.10/site-packages/pymysql/connections.py", line 669, in connect
    self._request_authentication()
  File "/home/johnatas/nexforce/env/lib/python3.10/site-packages/pymysql/connections.py", line 957, in _request_authentication
    auth_packet = self._read_packet()
  File "/home/johnatas/nexforce/env/lib/python3.10/site-packages/pymysql/connections.py", line 775, in _read_packet
    packet.raise_for_error()
  File "/home/johnatas/nexforce/env/lib/python3.10/site-packages/pymysql/protocol.py", line 219, in raise_for_error
    err.raise_mysql_exception(self._data)
  File "/home/johnatas/nexforce/env/lib/python3.10/site-packages/pymysql/err.py", line 150, in raise_mysql_exception
    raise errorclass(errno, errval)
pymysql.err.OperationalError: (1045, "Access denied for user '_b7ebe10d1e52525e'@'localhost' (using password: YES)")
2025-02-13 02:12:00,325 ERROR scheduler Exception in Enqueue Events for Site commands-site-O4PN2QK.test
Traceback (most recent call last):
  File "/home/johnatas/nexforce/apps/frappe/frappe/utils/scheduler.py", line 105, in enqueue_events_for_site
    if is_scheduler_inactive():
  File "/home/johnatas/nexforce/apps/frappe/frappe/utils/scheduler.py", line 149, in is_scheduler_inactive
    if is_scheduler_disabled(verbose=verbose):
  File "/home/johnatas/nexforce/apps/frappe/frappe/utils/scheduler.py", line 162, in is_scheduler_disabled
    frappe.db.get_single_value("System Settings", "enable_scheduler")
  File "/home/johnatas/nexforce/apps/frappe/frappe/database/database.py", line 869, in get_single_value
    ).run()
  File "/home/johnatas/nexforce/apps/frappe/frappe/query_builder/utils.py", line 84, in execute_query
    result = frappe.db.sql(query, params, *args, **kwargs)  # nosemgrep
  File "/home/johnatas/nexforce/apps/frappe/frappe/database/database.py", line 215, in sql
    self.connect()
  File "/home/johnatas/nexforce/apps/frappe/frappe/database/database.py", line 120, in connect
    self._conn: MariadbConnection | PostgresConnection = self.get_connection()
  File "/home/johnatas/nexforce/apps/frappe/frappe/database/mariadb/database.py", line 107, in get_connection
    conn = self._get_connection()
  File "/home/johnatas/nexforce/apps/frappe/frappe/database/mariadb/database.py", line 113, in _get_connection
    return self.create_connection()
  File "/home/johnatas/nexforce/apps/frappe/frappe/database/mariadb/database.py", line 116, in create_connection
    return pymysql.connect(**self.get_connection_settings())
  File "/home/johnatas/nexforce/env/lib/python3.10/site-packages/pymysql/connections.py", line 361, in __init__
    self.connect()
  File "/home/johnatas/nexforce/env/lib/python3.10/site-packages/pymysql/connections.py", line 669, in connect
    self._request_authentication()
  File "/home/johnatas/nexforce/env/lib/python3.10/site-packages/pymysql/connections.py", line 957, in _request_authentication
    auth_packet = self._read_packet()
  File "/home/johnatas/nexforce/env/lib/python3.10/site-packages/pymysql/connections.py", line 775, in _read_packet
    packet.raise_for_error()
  File "/home/johnatas/nexforce/env/lib/python3.10/site-packages/pymysql/protocol.py", line 219, in raise_for_error
    err.raise_mysql_exception(self._data)
  File "/home/johnatas/nexforce/env/lib/python3.10/site-packages/pymysql/err.py", line 150, in raise_mysql_exception
    raise errorclass(errno, errval)
pymysql.err.OperationalError: (1045, "Access denied for user '_b7ebe10d1e52525e'@'localhost' (using password: YES)")
2025-02-13 02:16:00,616 ERROR scheduler Exception in Enqueue Events for Site commands-site-O4PN2QK.test
Traceback (most recent call last):
  File "/home/johnatas/nexforce/apps/frappe/frappe/utils/scheduler.py", line 105, in enqueue_events_for_site
    if is_scheduler_inactive():
  File "/home/johnatas/nexforce/apps/frappe/frappe/utils/scheduler.py", line 149, in is_scheduler_inactive
    if is_scheduler_disabled(verbose=verbose):
  File "/home/johnatas/nexforce/apps/frappe/frappe/utils/scheduler.py", line 162, in is_scheduler_disabled
    frappe.db.get_single_value("System Settings", "enable_scheduler")
  File "/home/johnatas/nexforce/apps/frappe/frappe/database/database.py", line 869, in get_single_value
    ).run()
  File "/home/johnatas/nexforce/apps/frappe/frappe/query_builder/utils.py", line 84, in execute_query
    result = frappe.db.sql(query, params, *args, **kwargs)  # nosemgrep
  File "/home/johnatas/nexforce/apps/frappe/frappe/database/database.py", line 215, in sql
    self.connect()
  File "/home/johnatas/nexforce/apps/frappe/frappe/database/database.py", line 120, in connect
    self._conn: MariadbConnection | PostgresConnection = self.get_connection()
  File "/home/johnatas/nexforce/apps/frappe/frappe/database/mariadb/database.py", line 107, in get_connection
    conn = self._get_connection()
  File "/home/johnatas/nexforce/apps/frappe/frappe/database/mariadb/database.py", line 113, in _get_connection
    return self.create_connection()
  File "/home/johnatas/nexforce/apps/frappe/frappe/database/mariadb/database.py", line 116, in create_connection
    return pymysql.connect(**self.get_connection_settings())
  File "/home/johnatas/nexforce/env/lib/python3.10/site-packages/pymysql/connections.py", line 361, in __init__
    self.connect()
  File "/home/johnatas/nexforce/env/lib/python3.10/site-packages/pymysql/connections.py", line 669, in connect
    self._request_authentication()
  File "/home/johnatas/nexforce/env/lib/python3.10/site-packages/pymysql/connections.py", line 957, in _request_authentication
    auth_packet = self._read_packet()
  File "/home/johnatas/nexforce/env/lib/python3.10/site-packages/pymysql/connections.py", line 775, in _read_packet
    packet.raise_for_error()
  File "/home/johnatas/nexforce/env/lib/python3.10/site-packages/pymysql/protocol.py", line 219, in raise_for_error
    err.raise_mysql_exception(self._data)
  File "/home/johnatas/nexforce/env/lib/python3.10/site-packages/pymysql/err.py", line 150, in raise_mysql_exception
    raise errorclass(errno, errval)
pymysql.err.OperationalError: (1045, "Access denied for user '_b7ebe10d1e52525e'@'localhost' (using password: YES)")
2025-02-13 02:20:57,875 ERROR scheduler Exception in Enqueue Events for Site commands-site-O4PN2QK.test
Traceback (most recent call last):
  File "/home/johnatas/nexforce/apps/frappe/frappe/utils/scheduler.py", line 105, in enqueue_events_for_site
    if is_scheduler_inactive():
  File "/home/johnatas/nexforce/apps/frappe/frappe/utils/scheduler.py", line 149, in is_scheduler_inactive
    if is_scheduler_disabled(verbose=verbose):
  File "/home/johnatas/nexforce/apps/frappe/frappe/utils/scheduler.py", line 162, in is_scheduler_disabled
    frappe.db.get_single_value("System Settings", "enable_scheduler")
  File "/home/johnatas/nexforce/apps/frappe/frappe/database/database.py", line 869, in get_single_value
    ).run()
  File "/home/johnatas/nexforce/apps/frappe/frappe/query_builder/utils.py", line 84, in execute_query
    result = frappe.db.sql(query, params, *args, **kwargs)  # nosemgrep
  File "/home/johnatas/nexforce/apps/frappe/frappe/database/database.py", line 215, in sql
    self.connect()
  File "/home/johnatas/nexforce/apps/frappe/frappe/database/database.py", line 120, in connect
    self._conn: MariadbConnection | PostgresConnection = self.get_connection()
  File "/home/johnatas/nexforce/apps/frappe/frappe/database/mariadb/database.py", line 107, in get_connection
    conn = self._get_connection()
  File "/home/johnatas/nexforce/apps/frappe/frappe/database/mariadb/database.py", line 113, in _get_connection
    return self.create_connection()
  File "/home/johnatas/nexforce/apps/frappe/frappe/database/mariadb/database.py", line 116, in create_connection
    return pymysql.connect(**self.get_connection_settings())
  File "/home/johnatas/nexforce/env/lib/python3.10/site-packages/pymysql/connections.py", line 361, in __init__
    self.connect()
  File "/home/johnatas/nexforce/env/lib/python3.10/site-packages/pymysql/connections.py", line 669, in connect
    self._request_authentication()
  File "/home/johnatas/nexforce/env/lib/python3.10/site-packages/pymysql/connections.py", line 957, in _request_authentication
    auth_packet = self._read_packet()
  File "/home/johnatas/nexforce/env/lib/python3.10/site-packages/pymysql/connections.py", line 775, in _read_packet
    packet.raise_for_error()
  File "/home/johnatas/nexforce/env/lib/python3.10/site-packages/pymysql/protocol.py", line 219, in raise_for_error
    err.raise_mysql_exception(self._data)
  File "/home/johnatas/nexforce/env/lib/python3.10/site-packages/pymysql/err.py", line 150, in raise_mysql_exception
    raise errorclass(errno, errval)
pymysql.err.OperationalError: (1045, "Access denied for user '_b7ebe10d1e52525e'@'localhost' (using password: YES)")
2025-02-13 02:24:00,170 ERROR scheduler Exception in Enqueue Events for Site commands-site-O4PN2QK.test
Traceback (most recent call last):
  File "/home/johnatas/nexforce/apps/frappe/frappe/utils/scheduler.py", line 105, in enqueue_events_for_site
    if is_scheduler_inactive():
  File "/home/johnatas/nexforce/apps/frappe/frappe/utils/scheduler.py", line 149, in is_scheduler_inactive
    if is_scheduler_disabled(verbose=verbose):
  File "/home/johnatas/nexforce/apps/frappe/frappe/utils/scheduler.py", line 162, in is_scheduler_disabled
    frappe.db.get_single_value("System Settings", "enable_scheduler")
  File "/home/johnatas/nexforce/apps/frappe/frappe/database/database.py", line 869, in get_single_value
    ).run()
  File "/home/johnatas/nexforce/apps/frappe/frappe/query_builder/utils.py", line 84, in execute_query
    result = frappe.db.sql(query, params, *args, **kwargs)  # nosemgrep
  File "/home/johnatas/nexforce/apps/frappe/frappe/database/database.py", line 215, in sql
    self.connect()
  File "/home/johnatas/nexforce/apps/frappe/frappe/database/database.py", line 120, in connect
    self._conn: MariadbConnection | PostgresConnection = self.get_connection()
  File "/home/johnatas/nexforce/apps/frappe/frappe/database/mariadb/database.py", line 107, in get_connection
    conn = self._get_connection()
  File "/home/johnatas/nexforce/apps/frappe/frappe/database/mariadb/database.py", line 113, in _get_connection
    return self.create_connection()
  File "/home/johnatas/nexforce/apps/frappe/frappe/database/mariadb/database.py", line 116, in create_connection
    return pymysql.connect(**self.get_connection_settings())
  File "/home/johnatas/nexforce/env/lib/python3.10/site-packages/pymysql/connections.py", line 361, in __init__
    self.connect()
  File "/home/johnatas/nexforce/env/lib/python3.10/site-packages/pymysql/connections.py", line 669, in connect
    self._request_authentication()
  File "/home/johnatas/nexforce/env/lib/python3.10/site-packages/pymysql/connections.py", line 957, in _request_authentication
    auth_packet = self._read_packet()
  File "/home/johnatas/nexforce/env/lib/python3.10/site-packages/pymysql/connections.py", line 775, in _read_packet
    packet.raise_for_error()
  File "/home/johnatas/nexforce/env/lib/python3.10/site-packages/pymysql/protocol.py", line 219, in raise_for_error
    err.raise_mysql_exception(self._data)
  File "/home/johnatas/nexforce/env/lib/python3.10/site-packages/pymysql/err.py", line 150, in raise_mysql_exception
    raise errorclass(errno, errval)
pymysql.err.OperationalError: (1045, "Access denied for user '_b7ebe10d1e52525e'@'localhost' (using password: YES)")
2025-02-13 02:28:00,641 ERROR scheduler Exception in Enqueue Events for Site commands-site-O4PN2QK.test
Traceback (most recent call last):
  File "/home/johnatas/nexforce/apps/frappe/frappe/utils/scheduler.py", line 105, in enqueue_events_for_site
    if is_scheduler_inactive():
  File "/home/johnatas/nexforce/apps/frappe/frappe/utils/scheduler.py", line 149, in is_scheduler_inactive
    if is_scheduler_disabled(verbose=verbose):
  File "/home/johnatas/nexforce/apps/frappe/frappe/utils/scheduler.py", line 162, in is_scheduler_disabled
    frappe.db.get_single_value("System Settings", "enable_scheduler")
  File "/home/johnatas/nexforce/apps/frappe/frappe/database/database.py", line 869, in get_single_value
    ).run()
  File "/home/johnatas/nexforce/apps/frappe/frappe/query_builder/utils.py", line 84, in execute_query
    result = frappe.db.sql(query, params, *args, **kwargs)  # nosemgrep
  File "/home/johnatas/nexforce/apps/frappe/frappe/database/database.py", line 215, in sql
    self.connect()
  File "/home/johnatas/nexforce/apps/frappe/frappe/database/database.py", line 120, in connect
    self._conn: MariadbConnection | PostgresConnection = self.get_connection()
  File "/home/johnatas/nexforce/apps/frappe/frappe/database/mariadb/database.py", line 107, in get_connection
    conn = self._get_connection()
  File "/home/johnatas/nexforce/apps/frappe/frappe/database/mariadb/database.py", line 113, in _get_connection
    return self.create_connection()
  File "/home/johnatas/nexforce/apps/frappe/frappe/database/mariadb/database.py", line 116, in create_connection
    return pymysql.connect(**self.get_connection_settings())
  File "/home/johnatas/nexforce/env/lib/python3.10/site-packages/pymysql/connections.py", line 361, in __init__
    self.connect()
  File "/home/johnatas/nexforce/env/lib/python3.10/site-packages/pymysql/connections.py", line 669, in connect
    self._request_authentication()
  File "/home/johnatas/nexforce/env/lib/python3.10/site-packages/pymysql/connections.py", line 957, in _request_authentication
    auth_packet = self._read_packet()
  File "/home/johnatas/nexforce/env/lib/python3.10/site-packages/pymysql/connections.py", line 775, in _read_packet
    packet.raise_for_error()
  File "/home/johnatas/nexforce/env/lib/python3.10/site-packages/pymysql/protocol.py", line 219, in raise_for_error
    err.raise_mysql_exception(self._data)
  File "/home/johnatas/nexforce/env/lib/python3.10/site-packages/pymysql/err.py", line 150, in raise_mysql_exception
    raise errorclass(errno, errval)
pymysql.err.OperationalError: (1045, "Access denied for user '_b7ebe10d1e52525e'@'localhost' (using password: YES)")
2025-02-13 02:32:00,968 ERROR scheduler Exception in Enqueue Events for Site commands-site-O4PN2QK.test
Traceback (most recent call last):
  File "/home/johnatas/nexforce/apps/frappe/frappe/utils/scheduler.py", line 105, in enqueue_events_for_site
    if is_scheduler_inactive():
  File "/home/johnatas/nexforce/apps/frappe/frappe/utils/scheduler.py", line 149, in is_scheduler_inactive
    if is_scheduler_disabled(verbose=verbose):
  File "/home/johnatas/nexforce/apps/frappe/frappe/utils/scheduler.py", line 162, in is_scheduler_disabled
    frappe.db.get_single_value("System Settings", "enable_scheduler")
  File "/home/johnatas/nexforce/apps/frappe/frappe/database/database.py", line 869, in get_single_value
    ).run()
  File "/home/johnatas/nexforce/apps/frappe/frappe/query_builder/utils.py", line 84, in execute_query
    result = frappe.db.sql(query, params, *args, **kwargs)  # nosemgrep
  File "/home/johnatas/nexforce/apps/frappe/frappe/database/database.py", line 215, in sql
    self.connect()
  File "/home/johnatas/nexforce/apps/frappe/frappe/database/database.py", line 120, in connect
    self._conn: MariadbConnection | PostgresConnection = self.get_connection()
  File "/home/johnatas/nexforce/apps/frappe/frappe/database/mariadb/database.py", line 107, in get_connection
    conn = self._get_connection()
  File "/home/johnatas/nexforce/apps/frappe/frappe/database/mariadb/database.py", line 113, in _get_connection
    return self.create_connection()
  File "/home/johnatas/nexforce/apps/frappe/frappe/database/mariadb/database.py", line 116, in create_connection
    return pymysql.connect(**self.get_connection_settings())
  File "/home/johnatas/nexforce/env/lib/python3.10/site-packages/pymysql/connections.py", line 361, in __init__
    self.connect()
  File "/home/johnatas/nexforce/env/lib/python3.10/site-packages/pymysql/connections.py", line 669, in connect
    self._request_authentication()
  File "/home/johnatas/nexforce/env/lib/python3.10/site-packages/pymysql/connections.py", line 957, in _request_authentication
    auth_packet = self._read_packet()
  File "/home/johnatas/nexforce/env/lib/python3.10/site-packages/pymysql/connections.py", line 775, in _read_packet
    packet.raise_for_error()
  File "/home/johnatas/nexforce/env/lib/python3.10/site-packages/pymysql/protocol.py", line 219, in raise_for_error
    err.raise_mysql_exception(self._data)
  File "/home/johnatas/nexforce/env/lib/python3.10/site-packages/pymysql/err.py", line 150, in raise_mysql_exception
    raise errorclass(errno, errval)
pymysql.err.OperationalError: (1045, "Access denied for user '_b7ebe10d1e52525e'@'localhost' (using password: YES)")
2025-02-13 02:36:01,230 ERROR scheduler Exception in Enqueue Events for Site commands-site-O4PN2QK.test
Traceback (most recent call last):
  File "/home/johnatas/nexforce/apps/frappe/frappe/utils/scheduler.py", line 105, in enqueue_events_for_site
    if is_scheduler_inactive():
  File "/home/johnatas/nexforce/apps/frappe/frappe/utils/scheduler.py", line 149, in is_scheduler_inactive
    if is_scheduler_disabled(verbose=verbose):
  File "/home/johnatas/nexforce/apps/frappe/frappe/utils/scheduler.py", line 162, in is_scheduler_disabled
    frappe.db.get_single_value("System Settings", "enable_scheduler")
  File "/home/johnatas/nexforce/apps/frappe/frappe/database/database.py", line 869, in get_single_value
    ).run()
  File "/home/johnatas/nexforce/apps/frappe/frappe/query_builder/utils.py", line 84, in execute_query
    result = frappe.db.sql(query, params, *args, **kwargs)  # nosemgrep
  File "/home/johnatas/nexforce/apps/frappe/frappe/database/database.py", line 215, in sql
    self.connect()
  File "/home/johnatas/nexforce/apps/frappe/frappe/database/database.py", line 120, in connect
    self._conn: MariadbConnection | PostgresConnection = self.get_connection()
  File "/home/johnatas/nexforce/apps/frappe/frappe/database/mariadb/database.py", line 107, in get_connection
    conn = self._get_connection()
  File "/home/johnatas/nexforce/apps/frappe/frappe/database/mariadb/database.py", line 113, in _get_connection
    return self.create_connection()
  File "/home/johnatas/nexforce/apps/frappe/frappe/database/mariadb/database.py", line 116, in create_connection
    return pymysql.connect(**self.get_connection_settings())
  File "/home/johnatas/nexforce/env/lib/python3.10/site-packages/pymysql/connections.py", line 361, in __init__
    self.connect()
  File "/home/johnatas/nexforce/env/lib/python3.10/site-packages/pymysql/connections.py", line 669, in connect
    self._request_authentication()
  File "/home/johnatas/nexforce/env/lib/python3.10/site-packages/pymysql/connections.py", line 957, in _request_authentication
    auth_packet = self._read_packet()
  File "/home/johnatas/nexforce/env/lib/python3.10/site-packages/pymysql/connections.py", line 775, in _read_packet
    packet.raise_for_error()
  File "/home/johnatas/nexforce/env/lib/python3.10/site-packages/pymysql/protocol.py", line 219, in raise_for_error
    err.raise_mysql_exception(self._data)
  File "/home/johnatas/nexforce/env/lib/python3.10/site-packages/pymysql/err.py", line 150, in raise_mysql_exception
    raise errorclass(errno, errval)
pymysql.err.OperationalError: (1045, "Access denied for user '_b7ebe10d1e52525e'@'localhost' (using password: YES)")
2025-02-13 02:40:00,340 ERROR scheduler Exception in Enqueue Events for Site commands-site-O4PN2QK.test
Traceback (most recent call last):
  File "/home/johnatas/nexforce/apps/frappe/frappe/utils/scheduler.py", line 105, in enqueue_events_for_site
    if is_scheduler_inactive():
  File "/home/johnatas/nexforce/apps/frappe/frappe/utils/scheduler.py", line 149, in is_scheduler_inactive
    if is_scheduler_disabled(verbose=verbose):
  File "/home/johnatas/nexforce/apps/frappe/frappe/utils/scheduler.py", line 162, in is_scheduler_disabled
    frappe.db.get_single_value("System Settings", "enable_scheduler")
  File "/home/johnatas/nexforce/apps/frappe/frappe/database/database.py", line 869, in get_single_value
    ).run()
  File "/home/johnatas/nexforce/apps/frappe/frappe/query_builder/utils.py", line 84, in execute_query
    result = frappe.db.sql(query, params, *args, **kwargs)  # nosemgrep
  File "/home/johnatas/nexforce/apps/frappe/frappe/database/database.py", line 215, in sql
    self.connect()
  File "/home/johnatas/nexforce/apps/frappe/frappe/database/database.py", line 120, in connect
    self._conn: MariadbConnection | PostgresConnection = self.get_connection()
  File "/home/johnatas/nexforce/apps/frappe/frappe/database/mariadb/database.py", line 107, in get_connection
    conn = self._get_connection()
  File "/home/johnatas/nexforce/apps/frappe/frappe/database/mariadb/database.py", line 113, in _get_connection
    return self.create_connection()
  File "/home/johnatas/nexforce/apps/frappe/frappe/database/mariadb/database.py", line 116, in create_connection
    return pymysql.connect(**self.get_connection_settings())
  File "/home/johnatas/nexforce/env/lib/python3.10/site-packages/pymysql/connections.py", line 361, in __init__
    self.connect()
  File "/home/johnatas/nexforce/env/lib/python3.10/site-packages/pymysql/connections.py", line 669, in connect
    self._request_authentication()
  File "/home/johnatas/nexforce/env/lib/python3.10/site-packages/pymysql/connections.py", line 957, in _request_authentication
    auth_packet = self._read_packet()
  File "/home/johnatas/nexforce/env/lib/python3.10/site-packages/pymysql/connections.py", line 775, in _read_packet
    packet.raise_for_error()
  File "/home/johnatas/nexforce/env/lib/python3.10/site-packages/pymysql/protocol.py", line 219, in raise_for_error
    err.raise_mysql_exception(self._data)
  File "/home/johnatas/nexforce/env/lib/python3.10/site-packages/pymysql/err.py", line 150, in raise_mysql_exception
    raise errorclass(errno, errval)
pymysql.err.OperationalError: (1045, "Access denied for user '_b7ebe10d1e52525e'@'localhost' (using password: YES)")
2025-02-13 12:25:09,533 ERROR scheduler Exception in Enqueue Events for Site commands-site-O4PN2QK.test
Traceback (most recent call last):
  File "/home/johnatas/nexforce/apps/frappe/frappe/utils/scheduler.py", line 105, in enqueue_events_for_site
    if is_scheduler_inactive():
  File "/home/johnatas/nexforce/apps/frappe/frappe/utils/scheduler.py", line 149, in is_scheduler_inactive
    if is_scheduler_disabled(verbose=verbose):
  File "/home/johnatas/nexforce/apps/frappe/frappe/utils/scheduler.py", line 162, in is_scheduler_disabled
    frappe.db.get_single_value("System Settings", "enable_scheduler")
  File "/home/johnatas/nexforce/apps/frappe/frappe/database/database.py", line 869, in get_single_value
    ).run()
  File "/home/johnatas/nexforce/apps/frappe/frappe/query_builder/utils.py", line 84, in execute_query
    result = frappe.db.sql(query, params, *args, **kwargs)  # nosemgrep
  File "/home/johnatas/nexforce/apps/frappe/frappe/database/database.py", line 215, in sql
    self.connect()
  File "/home/johnatas/nexforce/apps/frappe/frappe/database/database.py", line 120, in connect
    self._conn: MariadbConnection | PostgresConnection = self.get_connection()
  File "/home/johnatas/nexforce/apps/frappe/frappe/database/mariadb/database.py", line 107, in get_connection
    conn = self._get_connection()
  File "/home/johnatas/nexforce/apps/frappe/frappe/database/mariadb/database.py", line 113, in _get_connection
    return self.create_connection()
  File "/home/johnatas/nexforce/apps/frappe/frappe/database/mariadb/database.py", line 116, in create_connection
    return pymysql.connect(**self.get_connection_settings())
  File "/home/johnatas/nexforce/env/lib/python3.10/site-packages/pymysql/connections.py", line 361, in __init__
    self.connect()
  File "/home/johnatas/nexforce/env/lib/python3.10/site-packages/pymysql/connections.py", line 669, in connect
    self._request_authentication()
  File "/home/johnatas/nexforce/env/lib/python3.10/site-packages/pymysql/connections.py", line 957, in _request_authentication
    auth_packet = self._read_packet()
  File "/home/johnatas/nexforce/env/lib/python3.10/site-packages/pymysql/connections.py", line 775, in _read_packet
    packet.raise_for_error()
  File "/home/johnatas/nexforce/env/lib/python3.10/site-packages/pymysql/protocol.py", line 219, in raise_for_error
    err.raise_mysql_exception(self._data)
  File "/home/johnatas/nexforce/env/lib/python3.10/site-packages/pymysql/err.py", line 150, in raise_mysql_exception
    raise errorclass(errno, errval)
pymysql.err.OperationalError: (1045, "Access denied for user '_b7ebe10d1e52525e'@'localhost' (using password: YES)")
2025-02-13 12:28:00,883 ERROR scheduler Exception in Enqueue Events for Site commands-site-O4PN2QK.test
Traceback (most recent call last):
  File "/home/johnatas/nexforce/apps/frappe/frappe/utils/scheduler.py", line 105, in enqueue_events_for_site
    if is_scheduler_inactive():
  File "/home/johnatas/nexforce/apps/frappe/frappe/utils/scheduler.py", line 149, in is_scheduler_inactive
    if is_scheduler_disabled(verbose=verbose):
  File "/home/johnatas/nexforce/apps/frappe/frappe/utils/scheduler.py", line 162, in is_scheduler_disabled
    frappe.db.get_single_value("System Settings", "enable_scheduler")
  File "/home/johnatas/nexforce/apps/frappe/frappe/database/database.py", line 869, in get_single_value
    ).run()
  File "/home/johnatas/nexforce/apps/frappe/frappe/query_builder/utils.py", line 84, in execute_query
    result = frappe.db.sql(query, params, *args, **kwargs)  # nosemgrep
  File "/home/johnatas/nexforce/apps/frappe/frappe/database/database.py", line 215, in sql
    self.connect()
  File "/home/johnatas/nexforce/apps/frappe/frappe/database/database.py", line 120, in connect
    self._conn: MariadbConnection | PostgresConnection = self.get_connection()
  File "/home/johnatas/nexforce/apps/frappe/frappe/database/mariadb/database.py", line 107, in get_connection
    conn = self._get_connection()
  File "/home/johnatas/nexforce/apps/frappe/frappe/database/mariadb/database.py", line 113, in _get_connection
    return self.create_connection()
  File "/home/johnatas/nexforce/apps/frappe/frappe/database/mariadb/database.py", line 116, in create_connection
    return pymysql.connect(**self.get_connection_settings())
  File "/home/johnatas/nexforce/env/lib/python3.10/site-packages/pymysql/connections.py", line 361, in __init__
    self.connect()
  File "/home/johnatas/nexforce/env/lib/python3.10/site-packages/pymysql/connections.py", line 669, in connect
    self._request_authentication()
  File "/home/johnatas/nexforce/env/lib/python3.10/site-packages/pymysql/connections.py", line 957, in _request_authentication
    auth_packet = self._read_packet()
  File "/home/johnatas/nexforce/env/lib/python3.10/site-packages/pymysql/connections.py", line 775, in _read_packet
    packet.raise_for_error()
  File "/home/johnatas/nexforce/env/lib/python3.10/site-packages/pymysql/protocol.py", line 219, in raise_for_error
    err.raise_mysql_exception(self._data)
  File "/home/johnatas/nexforce/env/lib/python3.10/site-packages/pymysql/err.py", line 150, in raise_mysql_exception
    raise errorclass(errno, errval)
pymysql.err.OperationalError: (1045, "Access denied for user '_b7ebe10d1e52525e'@'localhost' (using password: YES)")
2025-02-13 12:32:00,988 ERROR scheduler Exception in Enqueue Events for Site commands-site-O4PN2QK.test
Traceback (most recent call last):
  File "/home/johnatas/nexforce/apps/frappe/frappe/utils/scheduler.py", line 105, in enqueue_events_for_site
    if is_scheduler_inactive():
  File "/home/johnatas/nexforce/apps/frappe/frappe/utils/scheduler.py", line 149, in is_scheduler_inactive
    if is_scheduler_disabled(verbose=verbose):
  File "/home/johnatas/nexforce/apps/frappe/frappe/utils/scheduler.py", line 162, in is_scheduler_disabled
    frappe.db.get_single_value("System Settings", "enable_scheduler")
  File "/home/johnatas/nexforce/apps/frappe/frappe/database/database.py", line 869, in get_single_value
    ).run()
  File "/home/johnatas/nexforce/apps/frappe/frappe/query_builder/utils.py", line 84, in execute_query
    result = frappe.db.sql(query, params, *args, **kwargs)  # nosemgrep
  File "/home/johnatas/nexforce/apps/frappe/frappe/database/database.py", line 215, in sql
    self.connect()
  File "/home/johnatas/nexforce/apps/frappe/frappe/database/database.py", line 120, in connect
    self._conn: MariadbConnection | PostgresConnection = self.get_connection()
  File "/home/johnatas/nexforce/apps/frappe/frappe/database/mariadb/database.py", line 107, in get_connection
    conn = self._get_connection()
  File "/home/johnatas/nexforce/apps/frappe/frappe/database/mariadb/database.py", line 113, in _get_connection
    return self.create_connection()
  File "/home/johnatas/nexforce/apps/frappe/frappe/database/mariadb/database.py", line 116, in create_connection
    return pymysql.connect(**self.get_connection_settings())
  File "/home/johnatas/nexforce/env/lib/python3.10/site-packages/pymysql/connections.py", line 361, in __init__
    self.connect()
  File "/home/johnatas/nexforce/env/lib/python3.10/site-packages/pymysql/connections.py", line 669, in connect
    self._request_authentication()
  File "/home/johnatas/nexforce/env/lib/python3.10/site-packages/pymysql/connections.py", line 957, in _request_authentication
    auth_packet = self._read_packet()
  File "/home/johnatas/nexforce/env/lib/python3.10/site-packages/pymysql/connections.py", line 775, in _read_packet
    packet.raise_for_error()
  File "/home/johnatas/nexforce/env/lib/python3.10/site-packages/pymysql/protocol.py", line 219, in raise_for_error
    err.raise_mysql_exception(self._data)
  File "/home/johnatas/nexforce/env/lib/python3.10/site-packages/pymysql/err.py", line 150, in raise_mysql_exception
    raise errorclass(errno, errval)
pymysql.err.OperationalError: (1045, "Access denied for user '_b7ebe10d1e52525e'@'localhost' (using password: YES)")
2025-02-13 12:36:00,235 ERROR scheduler Exception in Enqueue Events for Site commands-site-O4PN2QK.test
Traceback (most recent call last):
  File "/home/johnatas/nexforce/apps/frappe/frappe/utils/scheduler.py", line 105, in enqueue_events_for_site
    if is_scheduler_inactive():
  File "/home/johnatas/nexforce/apps/frappe/frappe/utils/scheduler.py", line 149, in is_scheduler_inactive
    if is_scheduler_disabled(verbose=verbose):
  File "/home/johnatas/nexforce/apps/frappe/frappe/utils/scheduler.py", line 162, in is_scheduler_disabled
    frappe.db.get_single_value("System Settings", "enable_scheduler")
  File "/home/johnatas/nexforce/apps/frappe/frappe/database/database.py", line 869, in get_single_value
    ).run()
  File "/home/johnatas/nexforce/apps/frappe/frappe/query_builder/utils.py", line 84, in execute_query
    result = frappe.db.sql(query, params, *args, **kwargs)  # nosemgrep
  File "/home/johnatas/nexforce/apps/frappe/frappe/database/database.py", line 215, in sql
    self.connect()
  File "/home/johnatas/nexforce/apps/frappe/frappe/database/database.py", line 120, in connect
    self._conn: MariadbConnection | PostgresConnection = self.get_connection()
  File "/home/johnatas/nexforce/apps/frappe/frappe/database/mariadb/database.py", line 107, in get_connection
    conn = self._get_connection()
  File "/home/johnatas/nexforce/apps/frappe/frappe/database/mariadb/database.py", line 113, in _get_connection
    return self.create_connection()
  File "/home/johnatas/nexforce/apps/frappe/frappe/database/mariadb/database.py", line 116, in create_connection
    return pymysql.connect(**self.get_connection_settings())
  File "/home/johnatas/nexforce/env/lib/python3.10/site-packages/pymysql/connections.py", line 361, in __init__
    self.connect()
  File "/home/johnatas/nexforce/env/lib/python3.10/site-packages/pymysql/connections.py", line 669, in connect
    self._request_authentication()
  File "/home/johnatas/nexforce/env/lib/python3.10/site-packages/pymysql/connections.py", line 957, in _request_authentication
    auth_packet = self._read_packet()
  File "/home/johnatas/nexforce/env/lib/python3.10/site-packages/pymysql/connections.py", line 775, in _read_packet
    packet.raise_for_error()
  File "/home/johnatas/nexforce/env/lib/python3.10/site-packages/pymysql/protocol.py", line 219, in raise_for_error
    err.raise_mysql_exception(self._data)
  File "/home/johnatas/nexforce/env/lib/python3.10/site-packages/pymysql/err.py", line 150, in raise_mysql_exception
    raise errorclass(errno, errval)
pymysql.err.OperationalError: (1045, "Access denied for user '_b7ebe10d1e52525e'@'localhost' (using password: YES)")
2025-02-13 12:40:00,246 ERROR scheduler Exception in Enqueue Events for Site commands-site-O4PN2QK.test
Traceback (most recent call last):
  File "/home/johnatas/nexforce/apps/frappe/frappe/utils/scheduler.py", line 105, in enqueue_events_for_site
    if is_scheduler_inactive():
  File "/home/johnatas/nexforce/apps/frappe/frappe/utils/scheduler.py", line 149, in is_scheduler_inactive
    if is_scheduler_disabled(verbose=verbose):
  File "/home/johnatas/nexforce/apps/frappe/frappe/utils/scheduler.py", line 162, in is_scheduler_disabled
    frappe.db.get_single_value("System Settings", "enable_scheduler")
  File "/home/johnatas/nexforce/apps/frappe/frappe/database/database.py", line 869, in get_single_value
    ).run()
  File "/home/johnatas/nexforce/apps/frappe/frappe/query_builder/utils.py", line 84, in execute_query
    result = frappe.db.sql(query, params, *args, **kwargs)  # nosemgrep
  File "/home/johnatas/nexforce/apps/frappe/frappe/database/database.py", line 215, in sql
    self.connect()
  File "/home/johnatas/nexforce/apps/frappe/frappe/database/database.py", line 120, in connect
    self._conn: MariadbConnection | PostgresConnection = self.get_connection()
  File "/home/johnatas/nexforce/apps/frappe/frappe/database/mariadb/database.py", line 107, in get_connection
    conn = self._get_connection()
  File "/home/johnatas/nexforce/apps/frappe/frappe/database/mariadb/database.py", line 113, in _get_connection
    return self.create_connection()
  File "/home/johnatas/nexforce/apps/frappe/frappe/database/mariadb/database.py", line 116, in create_connection
    return pymysql.connect(**self.get_connection_settings())
  File "/home/johnatas/nexforce/env/lib/python3.10/site-packages/pymysql/connections.py", line 361, in __init__
    self.connect()
  File "/home/johnatas/nexforce/env/lib/python3.10/site-packages/pymysql/connections.py", line 669, in connect
    self._request_authentication()
  File "/home/johnatas/nexforce/env/lib/python3.10/site-packages/pymysql/connections.py", line 957, in _request_authentication
    auth_packet = self._read_packet()
  File "/home/johnatas/nexforce/env/lib/python3.10/site-packages/pymysql/connections.py", line 775, in _read_packet
    packet.raise_for_error()
  File "/home/johnatas/nexforce/env/lib/python3.10/site-packages/pymysql/protocol.py", line 219, in raise_for_error
    err.raise_mysql_exception(self._data)
  File "/home/johnatas/nexforce/env/lib/python3.10/site-packages/pymysql/err.py", line 150, in raise_mysql_exception
    raise errorclass(errno, errval)
pymysql.err.OperationalError: (1045, "Access denied for user '_b7ebe10d1e52525e'@'localhost' (using password: YES)")
2025-02-13 12:44:00,479 ERROR scheduler Exception in Enqueue Events for Site commands-site-O4PN2QK.test
Traceback (most recent call last):
  File "/home/johnatas/nexforce/apps/frappe/frappe/utils/scheduler.py", line 105, in enqueue_events_for_site
    if is_scheduler_inactive():
  File "/home/johnatas/nexforce/apps/frappe/frappe/utils/scheduler.py", line 149, in is_scheduler_inactive
    if is_scheduler_disabled(verbose=verbose):
  File "/home/johnatas/nexforce/apps/frappe/frappe/utils/scheduler.py", line 162, in is_scheduler_disabled
    frappe.db.get_single_value("System Settings", "enable_scheduler")
  File "/home/johnatas/nexforce/apps/frappe/frappe/database/database.py", line 869, in get_single_value
    ).run()
  File "/home/johnatas/nexforce/apps/frappe/frappe/query_builder/utils.py", line 84, in execute_query
    result = frappe.db.sql(query, params, *args, **kwargs)  # nosemgrep
  File "/home/johnatas/nexforce/apps/frappe/frappe/database/database.py", line 215, in sql
    self.connect()
  File "/home/johnatas/nexforce/apps/frappe/frappe/database/database.py", line 120, in connect
    self._conn: MariadbConnection | PostgresConnection = self.get_connection()
  File "/home/johnatas/nexforce/apps/frappe/frappe/database/mariadb/database.py", line 107, in get_connection
    conn = self._get_connection()
  File "/home/johnatas/nexforce/apps/frappe/frappe/database/mariadb/database.py", line 113, in _get_connection
    return self.create_connection()
  File "/home/johnatas/nexforce/apps/frappe/frappe/database/mariadb/database.py", line 116, in create_connection
    return pymysql.connect(**self.get_connection_settings())
  File "/home/johnatas/nexforce/env/lib/python3.10/site-packages/pymysql/connections.py", line 361, in __init__
    self.connect()
  File "/home/johnatas/nexforce/env/lib/python3.10/site-packages/pymysql/connections.py", line 669, in connect
    self._request_authentication()
  File "/home/johnatas/nexforce/env/lib/python3.10/site-packages/pymysql/connections.py", line 957, in _request_authentication
    auth_packet = self._read_packet()
  File "/home/johnatas/nexforce/env/lib/python3.10/site-packages/pymysql/connections.py", line 775, in _read_packet
    packet.raise_for_error()
  File "/home/johnatas/nexforce/env/lib/python3.10/site-packages/pymysql/protocol.py", line 219, in raise_for_error
    err.raise_mysql_exception(self._data)
  File "/home/johnatas/nexforce/env/lib/python3.10/site-packages/pymysql/err.py", line 150, in raise_mysql_exception
    raise errorclass(errno, errval)
pymysql.err.OperationalError: (1045, "Access denied for user '_b7ebe10d1e52525e'@'localhost' (using password: YES)")
2025-02-13 12:48:00,515 ERROR scheduler Exception in Enqueue Events for Site commands-site-O4PN2QK.test
Traceback (most recent call last):
  File "/home/johnatas/nexforce/apps/frappe/frappe/utils/scheduler.py", line 105, in enqueue_events_for_site
    if is_scheduler_inactive():
  File "/home/johnatas/nexforce/apps/frappe/frappe/utils/scheduler.py", line 149, in is_scheduler_inactive
    if is_scheduler_disabled(verbose=verbose):
  File "/home/johnatas/nexforce/apps/frappe/frappe/utils/scheduler.py", line 162, in is_scheduler_disabled
    frappe.db.get_single_value("System Settings", "enable_scheduler")
  File "/home/johnatas/nexforce/apps/frappe/frappe/database/database.py", line 869, in get_single_value
    ).run()
  File "/home/johnatas/nexforce/apps/frappe/frappe/query_builder/utils.py", line 84, in execute_query
    result = frappe.db.sql(query, params, *args, **kwargs)  # nosemgrep
  File "/home/johnatas/nexforce/apps/frappe/frappe/database/database.py", line 215, in sql
    self.connect()
  File "/home/johnatas/nexforce/apps/frappe/frappe/database/database.py", line 120, in connect
    self._conn: MariadbConnection | PostgresConnection = self.get_connection()
  File "/home/johnatas/nexforce/apps/frappe/frappe/database/mariadb/database.py", line 107, in get_connection
    conn = self._get_connection()
  File "/home/johnatas/nexforce/apps/frappe/frappe/database/mariadb/database.py", line 113, in _get_connection
    return self.create_connection()
  File "/home/johnatas/nexforce/apps/frappe/frappe/database/mariadb/database.py", line 116, in create_connection
    return pymysql.connect(**self.get_connection_settings())
  File "/home/johnatas/nexforce/env/lib/python3.10/site-packages/pymysql/connections.py", line 361, in __init__
    self.connect()
  File "/home/johnatas/nexforce/env/lib/python3.10/site-packages/pymysql/connections.py", line 669, in connect
    self._request_authentication()
  File "/home/johnatas/nexforce/env/lib/python3.10/site-packages/pymysql/connections.py", line 957, in _request_authentication
    auth_packet = self._read_packet()
  File "/home/johnatas/nexforce/env/lib/python3.10/site-packages/pymysql/connections.py", line 775, in _read_packet
    packet.raise_for_error()
  File "/home/johnatas/nexforce/env/lib/python3.10/site-packages/pymysql/protocol.py", line 219, in raise_for_error
    err.raise_mysql_exception(self._data)
  File "/home/johnatas/nexforce/env/lib/python3.10/site-packages/pymysql/err.py", line 150, in raise_mysql_exception
    raise errorclass(errno, errval)
pymysql.err.OperationalError: (1045, "Access denied for user '_b7ebe10d1e52525e'@'localhost' (using password: YES)")
2025-02-13 12:52:00,759 ERROR scheduler Exception in Enqueue Events for Site commands-site-O4PN2QK.test
Traceback (most recent call last):
  File "/home/johnatas/nexforce/apps/frappe/frappe/utils/scheduler.py", line 105, in enqueue_events_for_site
    if is_scheduler_inactive():
  File "/home/johnatas/nexforce/apps/frappe/frappe/utils/scheduler.py", line 149, in is_scheduler_inactive
    if is_scheduler_disabled(verbose=verbose):
  File "/home/johnatas/nexforce/apps/frappe/frappe/utils/scheduler.py", line 162, in is_scheduler_disabled
    frappe.db.get_single_value("System Settings", "enable_scheduler")
  File "/home/johnatas/nexforce/apps/frappe/frappe/database/database.py", line 869, in get_single_value
    ).run()
  File "/home/johnatas/nexforce/apps/frappe/frappe/query_builder/utils.py", line 84, in execute_query
    result = frappe.db.sql(query, params, *args, **kwargs)  # nosemgrep
  File "/home/johnatas/nexforce/apps/frappe/frappe/database/database.py", line 215, in sql
    self.connect()
  File "/home/johnatas/nexforce/apps/frappe/frappe/database/database.py", line 120, in connect
    self._conn: MariadbConnection | PostgresConnection = self.get_connection()
  File "/home/johnatas/nexforce/apps/frappe/frappe/database/mariadb/database.py", line 107, in get_connection
    conn = self._get_connection()
  File "/home/johnatas/nexforce/apps/frappe/frappe/database/mariadb/database.py", line 113, in _get_connection
    return self.create_connection()
  File "/home/johnatas/nexforce/apps/frappe/frappe/database/mariadb/database.py", line 116, in create_connection
    return pymysql.connect(**self.get_connection_settings())
  File "/home/johnatas/nexforce/env/lib/python3.10/site-packages/pymysql/connections.py", line 361, in __init__
    self.connect()
  File "/home/johnatas/nexforce/env/lib/python3.10/site-packages/pymysql/connections.py", line 669, in connect
    self._request_authentication()
  File "/home/johnatas/nexforce/env/lib/python3.10/site-packages/pymysql/connections.py", line 957, in _request_authentication
    auth_packet = self._read_packet()
  File "/home/johnatas/nexforce/env/lib/python3.10/site-packages/pymysql/connections.py", line 775, in _read_packet
    packet.raise_for_error()
  File "/home/johnatas/nexforce/env/lib/python3.10/site-packages/pymysql/protocol.py", line 219, in raise_for_error
    err.raise_mysql_exception(self._data)
  File "/home/johnatas/nexforce/env/lib/python3.10/site-packages/pymysql/err.py", line 150, in raise_mysql_exception
    raise errorclass(errno, errval)
pymysql.err.OperationalError: (1045, "Access denied for user '_b7ebe10d1e52525e'@'localhost' (using password: YES)")
2025-02-13 12:56:00,927 ERROR scheduler Exception in Enqueue Events for Site commands-site-O4PN2QK.test
Traceback (most recent call last):
  File "/home/johnatas/nexforce/apps/frappe/frappe/utils/scheduler.py", line 105, in enqueue_events_for_site
    if is_scheduler_inactive():
  File "/home/johnatas/nexforce/apps/frappe/frappe/utils/scheduler.py", line 149, in is_scheduler_inactive
    if is_scheduler_disabled(verbose=verbose):
  File "/home/johnatas/nexforce/apps/frappe/frappe/utils/scheduler.py", line 162, in is_scheduler_disabled
    frappe.db.get_single_value("System Settings", "enable_scheduler")
  File "/home/johnatas/nexforce/apps/frappe/frappe/database/database.py", line 869, in get_single_value
    ).run()
  File "/home/johnatas/nexforce/apps/frappe/frappe/query_builder/utils.py", line 84, in execute_query
    result = frappe.db.sql(query, params, *args, **kwargs)  # nosemgrep
  File "/home/johnatas/nexforce/apps/frappe/frappe/database/database.py", line 215, in sql
    self.connect()
  File "/home/johnatas/nexforce/apps/frappe/frappe/database/database.py", line 120, in connect
    self._conn: MariadbConnection | PostgresConnection = self.get_connection()
  File "/home/johnatas/nexforce/apps/frappe/frappe/database/mariadb/database.py", line 107, in get_connection
    conn = self._get_connection()
  File "/home/johnatas/nexforce/apps/frappe/frappe/database/mariadb/database.py", line 113, in _get_connection
    return self.create_connection()
  File "/home/johnatas/nexforce/apps/frappe/frappe/database/mariadb/database.py", line 116, in create_connection
    return pymysql.connect(**self.get_connection_settings())
  File "/home/johnatas/nexforce/env/lib/python3.10/site-packages/pymysql/connections.py", line 361, in __init__
    self.connect()
  File "/home/johnatas/nexforce/env/lib/python3.10/site-packages/pymysql/connections.py", line 669, in connect
    self._request_authentication()
  File "/home/johnatas/nexforce/env/lib/python3.10/site-packages/pymysql/connections.py", line 957, in _request_authentication
    auth_packet = self._read_packet()
  File "/home/johnatas/nexforce/env/lib/python3.10/site-packages/pymysql/connections.py", line 775, in _read_packet
    packet.raise_for_error()
  File "/home/johnatas/nexforce/env/lib/python3.10/site-packages/pymysql/protocol.py", line 219, in raise_for_error
    err.raise_mysql_exception(self._data)
  File "/home/johnatas/nexforce/env/lib/python3.10/site-packages/pymysql/err.py", line 150, in raise_mysql_exception
    raise errorclass(errno, errval)
pymysql.err.OperationalError: (1045, "Access denied for user '_b7ebe10d1e52525e'@'localhost' (using password: YES)")
2025-02-13 13:00:01,006 ERROR scheduler Exception in Enqueue Events for Site commands-site-O4PN2QK.test
Traceback (most recent call last):
  File "/home/johnatas/nexforce/apps/frappe/frappe/utils/scheduler.py", line 105, in enqueue_events_for_site
    if is_scheduler_inactive():
  File "/home/johnatas/nexforce/apps/frappe/frappe/utils/scheduler.py", line 149, in is_scheduler_inactive
    if is_scheduler_disabled(verbose=verbose):
  File "/home/johnatas/nexforce/apps/frappe/frappe/utils/scheduler.py", line 162, in is_scheduler_disabled
    frappe.db.get_single_value("System Settings", "enable_scheduler")
  File "/home/johnatas/nexforce/apps/frappe/frappe/database/database.py", line 869, in get_single_value
    ).run()
  File "/home/johnatas/nexforce/apps/frappe/frappe/query_builder/utils.py", line 84, in execute_query
    result = frappe.db.sql(query, params, *args, **kwargs)  # nosemgrep
  File "/home/johnatas/nexforce/apps/frappe/frappe/database/database.py", line 215, in sql
    self.connect()
  File "/home/johnatas/nexforce/apps/frappe/frappe/database/database.py", line 120, in connect
    self._conn: MariadbConnection | PostgresConnection = self.get_connection()
  File "/home/johnatas/nexforce/apps/frappe/frappe/database/mariadb/database.py", line 107, in get_connection
    conn = self._get_connection()
  File "/home/johnatas/nexforce/apps/frappe/frappe/database/mariadb/database.py", line 113, in _get_connection
    return self.create_connection()
  File "/home/johnatas/nexforce/apps/frappe/frappe/database/mariadb/database.py", line 116, in create_connection
    return pymysql.connect(**self.get_connection_settings())
  File "/home/johnatas/nexforce/env/lib/python3.10/site-packages/pymysql/connections.py", line 361, in __init__
    self.connect()
  File "/home/johnatas/nexforce/env/lib/python3.10/site-packages/pymysql/connections.py", line 669, in connect
    self._request_authentication()
  File "/home/johnatas/nexforce/env/lib/python3.10/site-packages/pymysql/connections.py", line 957, in _request_authentication
    auth_packet = self._read_packet()
  File "/home/johnatas/nexforce/env/lib/python3.10/site-packages/pymysql/connections.py", line 775, in _read_packet
    packet.raise_for_error()
  File "/home/johnatas/nexforce/env/lib/python3.10/site-packages/pymysql/protocol.py", line 219, in raise_for_error
    err.raise_mysql_exception(self._data)
  File "/home/johnatas/nexforce/env/lib/python3.10/site-packages/pymysql/err.py", line 150, in raise_mysql_exception
    raise errorclass(errno, errval)
pymysql.err.OperationalError: (1045, "Access denied for user '_b7ebe10d1e52525e'@'localhost' (using password: YES)")
2025-02-13 13:04:00,288 ERROR scheduler Exception in Enqueue Events for Site commands-site-O4PN2QK.test
Traceback (most recent call last):
  File "/home/johnatas/nexforce/apps/frappe/frappe/utils/scheduler.py", line 105, in enqueue_events_for_site
    if is_scheduler_inactive():
  File "/home/johnatas/nexforce/apps/frappe/frappe/utils/scheduler.py", line 149, in is_scheduler_inactive
    if is_scheduler_disabled(verbose=verbose):
  File "/home/johnatas/nexforce/apps/frappe/frappe/utils/scheduler.py", line 162, in is_scheduler_disabled
    frappe.db.get_single_value("System Settings", "enable_scheduler")
  File "/home/johnatas/nexforce/apps/frappe/frappe/database/database.py", line 869, in get_single_value
    ).run()
  File "/home/johnatas/nexforce/apps/frappe/frappe/query_builder/utils.py", line 84, in execute_query
    result = frappe.db.sql(query, params, *args, **kwargs)  # nosemgrep
  File "/home/johnatas/nexforce/apps/frappe/frappe/database/database.py", line 215, in sql
    self.connect()
  File "/home/johnatas/nexforce/apps/frappe/frappe/database/database.py", line 120, in connect
    self._conn: MariadbConnection | PostgresConnection = self.get_connection()
  File "/home/johnatas/nexforce/apps/frappe/frappe/database/mariadb/database.py", line 107, in get_connection
    conn = self._get_connection()
  File "/home/johnatas/nexforce/apps/frappe/frappe/database/mariadb/database.py", line 113, in _get_connection
    return self.create_connection()
  File "/home/johnatas/nexforce/apps/frappe/frappe/database/mariadb/database.py", line 116, in create_connection
    return pymysql.connect(**self.get_connection_settings())
  File "/home/johnatas/nexforce/env/lib/python3.10/site-packages/pymysql/connections.py", line 361, in __init__
    self.connect()
  File "/home/johnatas/nexforce/env/lib/python3.10/site-packages/pymysql/connections.py", line 669, in connect
    self._request_authentication()
  File "/home/johnatas/nexforce/env/lib/python3.10/site-packages/pymysql/connections.py", line 957, in _request_authentication
    auth_packet = self._read_packet()
  File "/home/johnatas/nexforce/env/lib/python3.10/site-packages/pymysql/connections.py", line 775, in _read_packet
    packet.raise_for_error()
  File "/home/johnatas/nexforce/env/lib/python3.10/site-packages/pymysql/protocol.py", line 219, in raise_for_error
    err.raise_mysql_exception(self._data)
  File "/home/johnatas/nexforce/env/lib/python3.10/site-packages/pymysql/err.py", line 150, in raise_mysql_exception
    raise errorclass(errno, errval)
pymysql.err.OperationalError: (1045, "Access denied for user '_b7ebe10d1e52525e'@'localhost' (using password: YES)")
2025-02-13 13:08:00,461 ERROR scheduler Exception in Enqueue Events for Site commands-site-O4PN2QK.test
Traceback (most recent call last):
  File "/home/johnatas/nexforce/apps/frappe/frappe/utils/scheduler.py", line 105, in enqueue_events_for_site
    if is_scheduler_inactive():
  File "/home/johnatas/nexforce/apps/frappe/frappe/utils/scheduler.py", line 149, in is_scheduler_inactive
    if is_scheduler_disabled(verbose=verbose):
  File "/home/johnatas/nexforce/apps/frappe/frappe/utils/scheduler.py", line 162, in is_scheduler_disabled
    frappe.db.get_single_value("System Settings", "enable_scheduler")
  File "/home/johnatas/nexforce/apps/frappe/frappe/database/database.py", line 869, in get_single_value
    ).run()
  File "/home/johnatas/nexforce/apps/frappe/frappe/query_builder/utils.py", line 84, in execute_query
    result = frappe.db.sql(query, params, *args, **kwargs)  # nosemgrep
  File "/home/johnatas/nexforce/apps/frappe/frappe/database/database.py", line 215, in sql
    self.connect()
  File "/home/johnatas/nexforce/apps/frappe/frappe/database/database.py", line 120, in connect
    self._conn: MariadbConnection | PostgresConnection = self.get_connection()
  File "/home/johnatas/nexforce/apps/frappe/frappe/database/mariadb/database.py", line 107, in get_connection
    conn = self._get_connection()
  File "/home/johnatas/nexforce/apps/frappe/frappe/database/mariadb/database.py", line 113, in _get_connection
    return self.create_connection()
  File "/home/johnatas/nexforce/apps/frappe/frappe/database/mariadb/database.py", line 116, in create_connection
    return pymysql.connect(**self.get_connection_settings())
  File "/home/johnatas/nexforce/env/lib/python3.10/site-packages/pymysql/connections.py", line 361, in __init__
    self.connect()
  File "/home/johnatas/nexforce/env/lib/python3.10/site-packages/pymysql/connections.py", line 669, in connect
    self._request_authentication()
  File "/home/johnatas/nexforce/env/lib/python3.10/site-packages/pymysql/connections.py", line 957, in _request_authentication
    auth_packet = self._read_packet()
  File "/home/johnatas/nexforce/env/lib/python3.10/site-packages/pymysql/connections.py", line 775, in _read_packet
    packet.raise_for_error()
  File "/home/johnatas/nexforce/env/lib/python3.10/site-packages/pymysql/protocol.py", line 219, in raise_for_error
    err.raise_mysql_exception(self._data)
  File "/home/johnatas/nexforce/env/lib/python3.10/site-packages/pymysql/err.py", line 150, in raise_mysql_exception
    raise errorclass(errno, errval)
pymysql.err.OperationalError: (1045, "Access denied for user '_b7ebe10d1e52525e'@'localhost' (using password: YES)")
2025-02-13 13:12:00,564 ERROR scheduler Exception in Enqueue Events for Site commands-site-O4PN2QK.test
Traceback (most recent call last):
  File "/home/johnatas/nexforce/apps/frappe/frappe/utils/scheduler.py", line 105, in enqueue_events_for_site
    if is_scheduler_inactive():
  File "/home/johnatas/nexforce/apps/frappe/frappe/utils/scheduler.py", line 149, in is_scheduler_inactive
    if is_scheduler_disabled(verbose=verbose):
  File "/home/johnatas/nexforce/apps/frappe/frappe/utils/scheduler.py", line 162, in is_scheduler_disabled
    frappe.db.get_single_value("System Settings", "enable_scheduler")
  File "/home/johnatas/nexforce/apps/frappe/frappe/database/database.py", line 869, in get_single_value
    ).run()
  File "/home/johnatas/nexforce/apps/frappe/frappe/query_builder/utils.py", line 84, in execute_query
    result = frappe.db.sql(query, params, *args, **kwargs)  # nosemgrep
  File "/home/johnatas/nexforce/apps/frappe/frappe/database/database.py", line 215, in sql
    self.connect()
  File "/home/johnatas/nexforce/apps/frappe/frappe/database/database.py", line 120, in connect
    self._conn: MariadbConnection | PostgresConnection = self.get_connection()
  File "/home/johnatas/nexforce/apps/frappe/frappe/database/mariadb/database.py", line 107, in get_connection
    conn = self._get_connection()
  File "/home/johnatas/nexforce/apps/frappe/frappe/database/mariadb/database.py", line 113, in _get_connection
    return self.create_connection()
  File "/home/johnatas/nexforce/apps/frappe/frappe/database/mariadb/database.py", line 116, in create_connection
    return pymysql.connect(**self.get_connection_settings())
  File "/home/johnatas/nexforce/env/lib/python3.10/site-packages/pymysql/connections.py", line 361, in __init__
    self.connect()
  File "/home/johnatas/nexforce/env/lib/python3.10/site-packages/pymysql/connections.py", line 669, in connect
    self._request_authentication()
  File "/home/johnatas/nexforce/env/lib/python3.10/site-packages/pymysql/connections.py", line 957, in _request_authentication
    auth_packet = self._read_packet()
  File "/home/johnatas/nexforce/env/lib/python3.10/site-packages/pymysql/connections.py", line 775, in _read_packet
    packet.raise_for_error()
  File "/home/johnatas/nexforce/env/lib/python3.10/site-packages/pymysql/protocol.py", line 219, in raise_for_error
    err.raise_mysql_exception(self._data)
  File "/home/johnatas/nexforce/env/lib/python3.10/site-packages/pymysql/err.py", line 150, in raise_mysql_exception
    raise errorclass(errno, errval)
pymysql.err.OperationalError: (1045, "Access denied for user '_b7ebe10d1e52525e'@'localhost' (using password: YES)")
2025-02-13 13:16:00,736 ERROR scheduler Exception in Enqueue Events for Site commands-site-O4PN2QK.test
Traceback (most recent call last):
  File "/home/johnatas/nexforce/apps/frappe/frappe/utils/scheduler.py", line 105, in enqueue_events_for_site
    if is_scheduler_inactive():
  File "/home/johnatas/nexforce/apps/frappe/frappe/utils/scheduler.py", line 149, in is_scheduler_inactive
    if is_scheduler_disabled(verbose=verbose):
  File "/home/johnatas/nexforce/apps/frappe/frappe/utils/scheduler.py", line 162, in is_scheduler_disabled
    frappe.db.get_single_value("System Settings", "enable_scheduler")
  File "/home/johnatas/nexforce/apps/frappe/frappe/database/database.py", line 869, in get_single_value
    ).run()
  File "/home/johnatas/nexforce/apps/frappe/frappe/query_builder/utils.py", line 84, in execute_query
    result = frappe.db.sql(query, params, *args, **kwargs)  # nosemgrep
  File "/home/johnatas/nexforce/apps/frappe/frappe/database/database.py", line 215, in sql
    self.connect()
  File "/home/johnatas/nexforce/apps/frappe/frappe/database/database.py", line 120, in connect
    self._conn: MariadbConnection | PostgresConnection = self.get_connection()
  File "/home/johnatas/nexforce/apps/frappe/frappe/database/mariadb/database.py", line 107, in get_connection
    conn = self._get_connection()
  File "/home/johnatas/nexforce/apps/frappe/frappe/database/mariadb/database.py", line 113, in _get_connection
    return self.create_connection()
  File "/home/johnatas/nexforce/apps/frappe/frappe/database/mariadb/database.py", line 116, in create_connection
    return pymysql.connect(**self.get_connection_settings())
  File "/home/johnatas/nexforce/env/lib/python3.10/site-packages/pymysql/connections.py", line 361, in __init__
    self.connect()
  File "/home/johnatas/nexforce/env/lib/python3.10/site-packages/pymysql/connections.py", line 669, in connect
    self._request_authentication()
  File "/home/johnatas/nexforce/env/lib/python3.10/site-packages/pymysql/connections.py", line 957, in _request_authentication
    auth_packet = self._read_packet()
  File "/home/johnatas/nexforce/env/lib/python3.10/site-packages/pymysql/connections.py", line 775, in _read_packet
    packet.raise_for_error()
  File "/home/johnatas/nexforce/env/lib/python3.10/site-packages/pymysql/protocol.py", line 219, in raise_for_error
    err.raise_mysql_exception(self._data)
  File "/home/johnatas/nexforce/env/lib/python3.10/site-packages/pymysql/err.py", line 150, in raise_mysql_exception
    raise errorclass(errno, errval)
pymysql.err.OperationalError: (1045, "Access denied for user '_b7ebe10d1e52525e'@'localhost' (using password: YES)")
2025-02-13 13:20:00,839 ERROR scheduler Exception in Enqueue Events for Site commands-site-O4PN2QK.test
Traceback (most recent call last):
  File "/home/johnatas/nexforce/apps/frappe/frappe/utils/scheduler.py", line 105, in enqueue_events_for_site
    if is_scheduler_inactive():
  File "/home/johnatas/nexforce/apps/frappe/frappe/utils/scheduler.py", line 149, in is_scheduler_inactive
    if is_scheduler_disabled(verbose=verbose):
  File "/home/johnatas/nexforce/apps/frappe/frappe/utils/scheduler.py", line 162, in is_scheduler_disabled
    frappe.db.get_single_value("System Settings", "enable_scheduler")
  File "/home/johnatas/nexforce/apps/frappe/frappe/database/database.py", line 869, in get_single_value
    ).run()
  File "/home/johnatas/nexforce/apps/frappe/frappe/query_builder/utils.py", line 84, in execute_query
    result = frappe.db.sql(query, params, *args, **kwargs)  # nosemgrep
  File "/home/johnatas/nexforce/apps/frappe/frappe/database/database.py", line 215, in sql
    self.connect()
  File "/home/johnatas/nexforce/apps/frappe/frappe/database/database.py", line 120, in connect
    self._conn: MariadbConnection | PostgresConnection = self.get_connection()
  File "/home/johnatas/nexforce/apps/frappe/frappe/database/mariadb/database.py", line 107, in get_connection
    conn = self._get_connection()
  File "/home/johnatas/nexforce/apps/frappe/frappe/database/mariadb/database.py", line 113, in _get_connection
    return self.create_connection()
  File "/home/johnatas/nexforce/apps/frappe/frappe/database/mariadb/database.py", line 116, in create_connection
    return pymysql.connect(**self.get_connection_settings())
  File "/home/johnatas/nexforce/env/lib/python3.10/site-packages/pymysql/connections.py", line 361, in __init__
    self.connect()
  File "/home/johnatas/nexforce/env/lib/python3.10/site-packages/pymysql/connections.py", line 669, in connect
    self._request_authentication()
  File "/home/johnatas/nexforce/env/lib/python3.10/site-packages/pymysql/connections.py", line 957, in _request_authentication
    auth_packet = self._read_packet()
  File "/home/johnatas/nexforce/env/lib/python3.10/site-packages/pymysql/connections.py", line 775, in _read_packet
    packet.raise_for_error()
  File "/home/johnatas/nexforce/env/lib/python3.10/site-packages/pymysql/protocol.py", line 219, in raise_for_error
    err.raise_mysql_exception(self._data)
  File "/home/johnatas/nexforce/env/lib/python3.10/site-packages/pymysql/err.py", line 150, in raise_mysql_exception
    raise errorclass(errno, errval)
pymysql.err.OperationalError: (1045, "Access denied for user '_b7ebe10d1e52525e'@'localhost' (using password: YES)")
